<mujoco model="rat">
<!--   <option timestep="0.001"/> -->
  <size njmax="2000" nconmax="1000"/>
  <visual>
    <quality shadowsize="2048"/>
<!--     <headlight ambient="0.4 0.4 0.4" diffuse="0.8 0.8 0.8" specular="0.1 0.1 0.1"/> -->
<!--     <map znear="0.0002"/> -->
  </visual>
  <default>
    <mesh scale="1 1 1"/>
    <joint limited="true" solreflimit="0.01 1" solimplimit="0.98999999999999999 0.99990000000000001 0" armature="6e-08" damping="0.0001"/>
    <geom friction="0.69999999999999996 0.0050000000000000001 0.0001" solref="0.0050000000000000001 1"/>
    <site group="3" rgba="0 0 1 1"/>
    <general ctrllimited="true" ctrlrange="-1 1" gainprm="0.01"/>
    <default class="bone">
      <geom contype="0" conaffinity="0" group="0" rgba="0.5 0.5 0.5 1" density="1100.0"/>
    </default>
    <default class="collision">
      <geom contype="1" conaffinity="1" condim="1" group="2"/>
      <default class="collision_primitive">
        <geom type="capsule" group="2" rgba="0 0.5 0.5 1" density="500.0"/>
        <default class="collision_primitive_paw">
          <geom condim="3" priority="1" rgba="0 0.59999999999999998 0.69999999999999996 1" friction="1.5 0.0050000000000000001 0.0001"/>
        </default>
        <default class="nonself_collision_primitive">
          <geom conaffinity="0"/>
        </default>
      </default>
      <default class="lumbar">
        <joint group="3" pos="0.0030000000000000001 0 -0.0030000000000000001" armature="1e-05" damping="0.03"/>
        <general gainprm="0.14999999999999999"/>
        <default class="lumbar_extend">
          <joint stiffness="0.02" range="-0.52359877559829882 0.26179938779914941"/>
          <tendon range="-1 1"/>
          <general gainprm="0.40000000000000002"/>
        </default>
        <default class="lumbar_bend">
          <joint stiffness="0.03" range="-0.52359877559829882 0.52359877559829882"/>
          <tendon range="-1 1"/>
        </default>
        <default class="lumbar_twist">
          <joint stiffness="0.03" range="-0.52359877559829882 0.52359877559829882"/>
          <tendon range="-1 1"/>
        </default>
      </default>
      <default class="cervical">
        <joint group="3" pos="-0.02 0 -0.050000000000000003" stiffness="1.0" armature="0.001" damping="5.0"/>
        <default class="cervical_extend">
          <joint range="-0.40724349213201022 0.6108652381980153"/>
          <tendon range="-1 1"/>
          <general gainprm="0.5"/>
        </default>
        <default class="cervical_bend">
          <joint range="-0.6108652381980153 0.6108652381980153"/>
          <tendon range="-1 1"/>
          <general gainprm="0.5"/>
        </default>
        <default class="cervical_twist">
          <joint range="-0.6108652381980153 0.6108652381980153"/>
          <tendon range="-1 1"/>
          <general gainprm="0.5"/>
        </default>
      </default>
      <default class="atlas">
        <joint axis="0 -1 0" stiffness="0.002" range="-0.087266462599716474 0.78539816339744828" damping="0.002"/>
        <general gainprm="0.025000000000000001"/>
      </default>
      <default class="mandible">
        <joint stiffness="0.002" range="-0.29670597283903599 0.26179938779914941" springref="-0.314159265359" damping="0.002"/>
        <general gainprm="0.025000000000000001"/>
      </default>
      <default class="caudal">
        <joint group="3" stiffness="1e-05" damping="0.01"/>
        <general gainprm="0.0050000000000000001"/>
        <default class="caudal_extend">
          <joint range="-0.1308996938995747 0.1308996938995747"/>
          <tendon range="-0.050000000000000003 0.050000000000000003"/>
        </default>
        <default class="caudal_bend">
          <joint range="-0.14959965017094251 0.14959965017094251"/>
          <tendon range="-0.20000000000000001 0.20000000000000001"/>
        </default>
      </default>
      <default class="hip">
        <joint armature="1e-05" damping="0.02"/>
        <general gainprm="0.14999999999999999"/>
        <default class="hip_supinate">
          <joint range="-0.52359877559829882 0.52359877559829882"/>
        </default>
        <default class="hip_abduct">
          <joint range="-0.3490658503988659 1.0471975511965981"/>
        </default>
        <default class="hip_extend">
          <joint range="-1.570796326794897 1.0471975511965981"/>
          <general gainprm="0.14999999999999999"/>
        </default>
      </default>
      <default class="knee">
        <joint range="-1.2217304763960311 1.5358897417550099" damping="0.005"/>
        <general gainprm="0.074999999999999997"/>
      </default>
      <default class="ankle">
        <joint range="-0.13962634015954639 1.396263401595464" damping="0.003"/>
        <general gainprm="0.050000000000000003"/>
      </default>
      <default class="toe">
        <joint range="0 0.87266462599716477" damping="0.0001"/>
        <general gainprm="0.0025000000000000001"/>
      </default>
      <default class="scapula">
        <joint damping="0.005"/>
        <general gainprm="0.25"/>
        <default class="scapula_supinate">
          <joint pos="0 0.005000000000000001 0" range="-0.017453292519943299 0.17453292519943289"/>
        </default>
        <default class="scapula_abduct">
          <joint pos="0 0.005000000000000001 -0.01" range="-0.26179938779914941 0.26179938779914941"/>
        </default>
        <default class="scapula_extend">
          <joint pos="0 0 0" range="-0.034906585039886591 0.034906585039886591"/>
          <general gainprm="0.25"/>
        </default>
      </default>
      <default class="shoulder">
        <joint range="-1.308996938995747 0.87266462599716477" damping="0.005"/>
        <general gainprm="0.14999999999999999"/>
      </default>
      <default class="shoulder_sup">
        <joint range="-0.05235987755982989 0.78539816339744828" damping="0.005"/>
        <general gainprm="0.14999999999999999"/>
      </default>
      <default class="elbow">
        <joint range="-1.308996938995747 0.52359877559829882" damping="0.003"/>
        <general gainprm="0.14999999999999999"/>
      </default>
      <default class="wrist">
        <joint range="-0.3490658503988659 2.0943951023931948" damping="0.002"/>
        <general gainprm="0.050000000000000003"/>
      </default>
      <default class="finger">
        <joint range="0 1.570796326794897" damping="0.002"/>
        <general gainprm="0.025000000000000001"/>
      </default>
      <default class="sensor">
        <site group="4"/>
      </default>
    </default>
  </default>
  <statistic meansize="0.003"/>
  <asset>
    <texture name="skybox" type="skybox" builtin="gradient" rgb1="0.40000000000000002 0.59999999999999998 0.80000000000000004" rgb2="0 0 0" mark="random" markrgb="1 1 1" width="800" height="800"/>
    <texture name="grid" type="2d" builtin="checker" rgb1="0.10000000000000001 0.20000000000000001 0.29999999999999999" rgb2="0.20000000000000001 0.29999999999999999 0.40000000000000002" mark="edge" markrgb="0.20000000000000001 0.29999999999999999 0.40000000000000002" width="300" height="300"/>
    <material name="grid" texture="grid" texrepeat="1 1" texuniform="true" reflectance="0.2"/>
    <material name="self" rgba="0.69999999999999996 0.5 0.29999999999999999 1"/>
    <material name="self_default" rgba="0.69999999999999996 0.5 0.29999999999999999 1"/>
    <material name="self_highlight" rgba="0 0.5 0.29999999999999999 1"/>
    <material name="effector" rgba="0.69999999999999996 0.40000000000000002 0.20000000000000001 1"/>
    <material name="effector_default" rgba="0.69999999999999996 0.40000000000000002 0.20000000000000001 1"/>
    <material name="effector_highlight" rgba="0 0.5 0.29999999999999999 1"/>
    <material name="decoration" rgba="0.29999999999999999 0.5 0.69999999999999996 1"/>
    <material name="eye" rgba="0 0.20000000000000001 1 1"/>
    <material name="target" rgba="0.59999999999999998 0.29999999999999999 0.29999999999999999 1"/>
    <material name="target_default" rgba="0.59999999999999998 0.29999999999999999 0.29999999999999999 1"/>
    <material name="target_highlight" rgba="0.59999999999999998 0.29999999999999999 0.29999999999999999 0.40000000000000002"/>
    <skin name="skin" file="rat_skin.skn"/>
  </asset>
  <worldbody>
    <geom name="floor" type="plane" size="20 20 0.10000000000000001" material="grid"/>
    <body name="torso" pos="0.037799098226564493 2.5103962654286069e-07 0.079377527599024">
      <freejoint name="root"/>
      <light name="light" mode="trackcom" pos="0 0 3"/>
      <camera name="back" mode="trackcom" pos="-1 0 0.5" xyaxes="0 -1 0 1 0 2"/>
      <camera name="side" mode="trackcom" pos="0 -1 0.5" xyaxes="1 0 0 0 1 2"/>
      <camera name="top" mode="trackcom" fovy="100.0" pos="0 0 1" zaxis="0 -0.20000000000000001 1"/>
      <geom name="collision_torso" class="nonself_collision_primitive" type="ellipsoid" size="0.050000000000000003 0.024 0.025999999999999999" density="600.0" pos="-0.01 0 0" euler="0 0.17453292519943289 0"/>
      <body name="vertebra_1" pos="-0.023389565447083569 -2.2930921862914259e-07 0.020544459642062061">
        <geom name="vertebra_1_collision" class="nonself_collision_primitive" type="sphere" size="0.01" pos="0 0 -0.002"/>
        <body name="vertebra_2" pos="-0.0068655077259972162 3.1643946203151751e-06 0.00064889301204673622">
          <geom name="vertebra_2_collision" class="nonself_collision_primitive" type="sphere" size="0.01" pos="0 0 -0.002"/>
          <body name="vertebra_3" pos="-0.0079477642348078168 -1.2695888601960559e-05 -0.00011545388896122549">
            <geom name="vertebra_3_collision" class="nonself_collision_primitive" type="sphere" size="0.01" pos="0 0 -0.002"/>
            <body name="vertebra_4" pos="-0.0082654929087646774 1.0665976984344999e-05 -0.001584530210795701">
              <geom name="vertebra_4_collision" class="nonself_collision_primitive" type="sphere" size="0.01" pos="0 0 -0.002"/>
              <body name="vertebra_5" pos="-0.008402520197930613 -7.5662605484429528e-06 -0.0030464207058322622">
                <geom name="vertebra_5_collision" class="nonself_collision_primitive" type="sphere" size="0.01" pos="0 0 -0.002"/>
                <body name="vertebra_6" pos="-0.0075430297983920883 6.4078562548232296e-06 -0.0044403932353997977">
                  <geom name="vertebra_6_collision" class="nonself_collision_primitive" type="sphere" size="0.01" pos="0 0 -0.002"/>
                  <joint name="vertebra_6_twist" class="lumbar_twist" axis="1 0 0"/>
                  <body name="pelvis" pos="-0.015940742925419461 4.2844163827084257e-06 -0.0099036375972835766">
                    <geom name="collision_pelvis_L" class="nonself_collision_primitive" size="0.012999999999999999 0.021000000000000001 0" pos="-0.001 0.0080000000000000002 -0.007000000000000001" euler="0 0.87266462599716477 0"/>
                    <geom name="collision_pelvis_R" class="nonself_collision_primitive" size="0.012999999999999999 0.021000000000000001 0" pos="-0.001 -0.0080000000000000002 -0.007000000000000001" euler="0 0.87266462599716477 0"/>
                    <geom name="collision_pelvis_gut" class="nonself_collision_primitive" type="ellipsoid" size="0.02 0.02 0.017999999999999999" pos="0.025000000000000001 0 -0.02" euler="0 -0.52359877559829882 0"/>
                    <site name="hip_L" size="0.0022000000000000001" pos="-0.0058662102643470913 0.01401372452038472 -0.01205832109893569"/>
                    <site name="hip_R" size="0.0022000000000000001" pos="-0.0058662102643470913 -0.01401372452038472 -0.01205832109893569"/>
                    <body name="upper_leg_L" pos="-0.0058662102643470913 0.01401372452038472 -0.01205832109893569">
                      <joint name="hip_L_supinate" class="hip_supinate" axis="-0 -0 1"/>
                      <joint name="hip_L_abduct" class="hip_abduct" axis="1 -0 -0"/>
                      <joint name="hip_L_extend" class="hip_extend" axis="0 1 0"/>
                      <site name="knee_L" type="cylinder" size="0.00060000000000000006 0.0040000000000000001" pos="0.016222667294645651 0.018385689600598405 -0.027037778824409418" zaxis="0 1 0"/>
                      <geom name="upper_leg_L0_collision" class="collision_primitive" size="0.0075406375174862606 0.015081275034972521" pos="0.0090487650209835121 0.011310956276229391 -0.013573147531475267" euler="0.6108652381980153 -0.69813170079773179 0"/>
                      <body name="lower_leg_L" pos="0.016222667294645651 0.018385689600598405 -0.027037778824409418">
                        <joint name="knee_L" class="knee" axis="0.5 -1 0"/>
                        <site name="ankle_L" type="cylinder" size="0.00060000000000000006 0.0025999999999999999" pos="-0.035088982905058325 -0.0051349731080573167 -0.023963207837600808" zaxis="0 1 0"/>
                        <body name="foot_L" pos="-0.035088982905058325 -0.0051349731080573167 -0.023963207837600808">
                          <joint name="ankle_L" class="ankle" axis="-0.29999999999999999 1 0"/>
                          <geom name="foot_L_collision" class="collision_primitive_paw" size="0.0028599785696990098 0.011031345911696178" pos="0.0089885040761968852 0.0024514102025991508 -0.0024514102025991508" euler="1.570796326794897 -1.2217304763960311 0"/>
                          <site name="toe_L" type="cylinder" size="0.00060000000000000006 0.005000000000000001" pos="0.021846843754864571 0.0078838610071902578 -0.0028495883158519003" zaxis="0 1 0"/>
                          <body name="toe_L" pos="0.021846843754864571 0.0078838610071902578 -0.0028495883158519003">
                            <joint name="toe_L" class="toe" axis="0 1 0"/>
                            <geom name="toe_L0_collision" class="collision_primitive_paw" size="0.0020234072231234434 0.006158195896462655" pos="0.008797422709232363 -0.0008797422709232363 0" euler="1.570796326794897 -1.2217304763960311 0"/>
                            <geom name="toe_L1_collision" class="collision_primitive_paw" size="0.0020234072231234434 0.0065980670319242722" pos="0.0083575515737707457 0.0026392268127697089 0" euler="1.570796326794897 -1.2217304763960311 0"/>
                            <geom name="toe_L2_collision" class="collision_primitive_paw" size="0.0020234072231234434 0.006158195896462655" pos="0.0070379381673858904 0.0057183247610010368 0" euler="1.570796326794897 -1.2217304763960311 0"/>
                            <site name="sole_L" class="sensor" type="box" size="0.0060000000000000001 0.0040000000000000001 0.002" pos="0.01 0.0030000000000000001 -0.002" euler="0 0 0.3490658503988659"/>
                          </body>
                        </body>
                        <geom name="lower_leg_L_collision" class="collision_primitive" size="0.0056554781381146953 0.016589402538469772" pos="-0.012899531761649629 0.00012883263272937942 -0.011274117531295055" quat="0.58439398761405215 0.27858155227390202 0.39004539538183519 0.65478284607542836"/>
                      </body>
                    </body>
                    <body name="upper_leg_R" pos="-0.0058662102643470913 -0.01401372452038472 -0.01205832109893569">
                      <joint name="hip_R_supinate" class="hip_supinate" axis="0 0 -1"/>
                      <joint name="hip_R_abduct" class="hip_abduct" axis="-1 0 0"/>
                      <joint name="hip_R_extend" class="hip_extend" axis="0 1 0"/>
                      <site name="knee_R" type="cylinder" size="0.00060000000000000006 0.0040000000000000001" pos="0.016222667294645651 -0.018385689600598405 -0.027037778824409418" zaxis="0 1 0"/>
                      <geom name="upper_leg_R0_collision" class="collision_primitive" size="0.0075406375174862606 0.015081275034972521" pos="0.0090487650209835121 -0.011310956276229391 -0.013573147531475267" euler="-0.6108652381980153 -0.69813170079773179 0"/>
                      <body name="lower_leg_R" pos="0.016222667294645651 -0.018385689600598405 -0.027037778824409418">
                        <joint name="knee_R" class="knee" axis="-0.5 -1 0"/>
                        <site name="ankle_R" type="cylinder" size="0.00060000000000000006 0.0025999999999999999" pos="-0.035088982905058325 0.0051349731080573167 -0.023963207837600808" zaxis="0 1 0"/>
                        <body name="foot_R" pos="-0.035088982905058325 0.0051349731080573167 -0.023963207837600808">
                          <joint name="ankle_R" class="ankle" axis="0.29999999999999999 1 0"/>
                          <geom name="foot_R_collision" class="collision_primitive_paw" size="0.0028599785696990098 0.011031345911696178" pos="0.0089885040761968852 -0.0024514102025991508 -0.0024514102025991508" euler="1.570796326794897 1.2217304763960311 0"/>
                          <site name="toe_R" type="cylinder" size="0.00060000000000000006 0.005000000000000001" pos="0.021846843754864571 -0.0078838610071902578 -0.0028495883158519003" zaxis="0 1 0"/>
                          <body name="toe_R" pos="0.021846843754864571 -0.0078838610071902578 -0.0028495883158519003">
                            <joint name="toe_R" class="toe" axis="0 1 0"/>
                            <geom name="toe_R0_collision" class="collision_primitive_paw" size="0.0020234072231234434 0.006158195896462655" pos="0.008797422709232363 0.0008797422709232363 0" euler="1.570796326794897 1.2217304763960311 0"/>
                            <geom name="toe_R1_collision" class="collision_primitive_paw" size="0.0020234072231234434 0.0065980670319242722" pos="0.0083575515737707457 -0.0026392268127697089 0" euler="1.570796326794897 1.2217304763960311 0"/>
                            <geom name="toe_R2_collision" class="collision_primitive_paw" size="0.0020234072231234434 0.006158195896462655" pos="0.0070379381673858904 -0.0057183247610010368 0" euler="1.570796326794897 1.2217304763960311 0"/>
                            <site name="sole_R" class="sensor" type="box" size="0.0060000000000000001 0.0040000000000000001 0.002" pos="0.01 -0.0030000000000000001 -0.002" euler="0 0 -0.3490658503988659"/>
                          </body>
                        </body>
                        <geom name="lower_leg_R_collision" class="collision_primitive" size="0.0056554781381146953 0.016589402538469772" pos="-0.012652947085481028 -0.00016996029920005856 -0.011122651214021499" quat="0.65643150361110036 0.39014177197659983 0.27795769268188453 0.58277491358567579"/>
                      </body>
                    </body>
                    <body name="vertebra_C1" pos="-0.01925598991443862 0 -0.01448978405632158">
                      <body name="vertebra_C2" pos="-0.0047281143684625828 0 -0.005154184395752763">
                        <body name="vertebra_C3" pos="-0.0041756424543784162 0 -0.0051988749220890362">
                          <body name="vertebra_C4" pos="-0.0039900910569002964 0 -0.0053863879905110684">
                            <body name="vertebra_C5" pos="-0.0038731393549012129 0 -0.0055723669014803232">
                              <body name="vertebra_C6" pos="-0.003803894939612194 0 -0.0059772625382232963">
                                <body name="vertebra_C7" pos="-0.0039217210601871057 0 -0.0068833794292660266">
                                  <body name="vertebra_C8" pos="-0.004202260371316764 0 -0.0067294893563231914">
                                    <body name="vertebra_C9" pos="-0.0052258204575372563 0 -0.006237827170811349">
                                      <body name="vertebra_C10" pos="-0.0059287136154180719 0 -0.0055636418812957007">
                                        <body name="vertebra_C11" pos="-0.006554618274265016 0 -0.0053222038646270238">
                                          <body name="vertebra_C12" pos="-0.00748107129343347 0 -0.0046847595145318036">
                                            <body name="vertebra_C13" pos="-0.0084114968905040378 0 -0.0031614977867951322">
                                              <body name="vertebra_C14" pos="-0.0083232167528583586 0 -0.0011084145040154089">
                                                <body name="vertebra_C15" pos="-0.0079587939867491794 0 -0.00038454999620317798">
                                                  <body name="vertebra_C16" pos="-0.0081633042047713524 0 -0.00016888844762884709">
                                                    <body name="vertebra_C17" pos="-0.0079090563985975953 0 -2.0371550478252e-05">
                                                      <body name="vertebra_C18" pos="-0.0075700392460947034 0 2.226308696857277e-10">
                                                        <body name="vertebra_C19" pos="-0.0075661702412505314 0 -1.0002319789483359e-09">
                                                          <body name="vertebra_C20" pos="-0.0075955814877348557 0 3.0689274058712328e-06">
                                                            <body name="vertebra_C21" pos="-0.0074605529481327777 0 -0.00013373679491688231">
                                                            <body name="vertebra_C22" pos="-0.0079367168896754912 0 -1.5999847361573639e-05">
                                                            <body name="vertebra_C23" pos="-0.0077936041617365417 0 2.135855378302375e-09">
                                                            <body name="vertebra_C24" pos="-0.0075374575551848642 0 -1.5208965527951919e-09">
                                                            <body name="vertebra_C25" pos="-0.0072782914045561153 0 1.6823077436320391e-10">
                                                            <body name="vertebra_C26" pos="-0.0068642397318802858 0 -1.6654026816463609e-09">
                                                            <body name="vertebra_C27" pos="-0.00633307351496559 0 1.7020645635100469e-09">
                                                            <body name="vertebra_C28" pos="-0.0061417550054283484 0 6.1877833610485006e-07">
                                                            <body name="vertebra_C29" pos="-0.0058218254111825959 0 -7.5677494761235142e-11">
                                                            <body name="vertebra_C30" pos="-0.0048845751499379626 0 -5.1185160818948035e-07">
                                                            <geom name="vertebra_C30_collision" class="collision_primitive" size="0.00077871372923254967 0.0061625257367268196 0.0034565399400889869" density="2000.0" pos="-4.163336342344337e-17 0 0" quat="0 0.70710678118654746 0 0.70710678118654757"/>
                                                            </body>
                                                            <joint name="vertebra_C29_extend" class="caudal_extend" pos="0.002618767786771059 0 3.4041176343692762e-11" axis="-0 1.0000000000000011 0" range="-0.26179938779914941 0.26179938779914941"/>
                                                            <geom name="vertebra_C29_collision" class="collision_primitive" size="0.00077809947542846199 0.0059637751837726682 0.002618767786771059" density="2000.0" pos="2.775557561562891e-17 0 0" quat="0 0.70710678118654746 0 0.70710678118654757"/>
                                                            </body>
                                                            <geom name="vertebra_C28_collision" class="collision_primitive" size="0.00077809940557926893 0.0057649202208267516 0.002877779770642519" density="2000.0" pos="-2.775557561562891e-17 0 0" quat="0 0.70710678118654746 0 0.70710678118654757"/>
                                                            </body>
                                                            <joint name="vertebra_C27_bend" class="caudal_bend" pos="0.0030614486895500512 0 -8.2278901629262446e-10" axis="-2.6875806186172678e-07 0 -0.99999999999996425" range="-0.26179938779914941 0.26179938779914941"/>
                                                            <geom name="vertebra_C27_collision" class="collision_primitive" size="0.00082776099443435667 0.0055661828373558819 0.0030614486895501609" density="2000.0" pos="-2.775557561562891e-17 -6.9388939039072284e-18 0" quat="0 0.70710678118654746 0 0.70710678118654757"/>
                                                            </body>
                                                            <geom name="vertebra_C26_collision" class="collision_primitive" size="0.0008277630200609565 0.0053673316579079264 0.0030614288989454512" density="2000.0" pos="0 0 0" quat="0 0.70710678118654746 0 0.70710678118654757"/>
                                                            </body>
                                                            <joint name="vertebra_C25_extend" class="caudal_extend" pos="0.0034789224155247198 0 -8.041197849633586e-11" axis="0 1 0" range="-0.26179938779914941 0.26179938779914941"/>
                                                            <geom name="vertebra_C25_collision" class="collision_primitive" size="0.00082776099443435667 0.0051685892685782164 0.0034789224155247211" density="2000.0" pos="2.775557561562891e-17 6.9388939039072284e-18 0" quat="0 0.70710678118654746 0 0.70710678118654757"/>
                                                            </body>
                                                            <geom name="vertebra_C24_collision" class="collision_primitive" size="0.00082776120398193593 0.0049697726353770122 0.0034789186902344231" density="2000.0" pos="0 6.9388939039072284e-18 0" quat="0 0.70710678118654746 0 0.70710678118654757"/>
                                                            </body>
                                                            <joint name="vertebra_C23_bend" class="caudal_bend" pos="0.0037407763302324802 0 -1.0251684686758591e-09" axis="-2.7405232983071981e-07 0 -0.99999999999996292" range="-0.26179938779914941 0.26179938779914941"/>
                                                            <geom name="vertebra_C23_collision" class="collision_primitive" size="0.00082775938790291548 0.0047709754435345531 0.0037407763302326198" density="2000.0" pos="0 0 0" quat="0 0.70710678118654746 0 0.70710678118654757"/>
                                                            </body>
                                                            <geom name="vertebra_C22_collision" class="collision_primitive" size="0.00082776197232306006 0.0045721781061729416 0.0037407784257084131" density="2000.0" pos="2.775557561562891e-17 0 0" quat="0 0.70710678118654746 0 0.70710678118654757"/>
                                                            </body>
                                                            <joint name="vertebra_C21_extend" class="caudal_extend" pos="0.0038531979682482919 0 6.9071870414476718e-05" axis="-0 1 0" range="-0.26179938779914941 0.26179938779914941"/>
                                                            <geom name="vertebra_C21_collision" class="collision_primitive" size="0.00091830915771424766 0.0049721287796273828 0.0038538170047104359" density="2000.0" pos="-2.775557561562891e-17 0 0" quat="0 0.70710678118654746 0 0.70710678118654757"/>
                                                            </body>
                                                            <geom name="vertebra_C20_collision" class="collision_primitive" size="0.00089897182770073405 0.0051765363605227321 0.0035961582325398922" density="2000.0" pos="0 3.4694469519536142e-18 0" quat="0 0.70710678118654746 0 0.70710678118654757"/>
                                                          </body>
                                                          <joint name="vertebra_C19_bend" class="caudal_bend" pos="0.0035962350666522672 0 4.7541480072307734e-10" axis="1.321979214127503e-07 0 -0.99999999999999156" range="-0.26179938779914941 0.26179938779914941"/>
                                                          <geom name="vertebra_C19_collision" class="collision_primitive" size="0.0009803724009543656 0.0051713781431317329 0.003596235066652298" density="2000.0" pos="0 0 0" quat="0 0.70710678118654746 0 0.70710678118654757"/>
                                                        </body>
                                                        <geom name="vertebra_C18_collision" class="collision_primitive" size="0.00098037365823984142 0.0049127749516628683 0.0035962301772087808" density="2000.0" pos="-5.5511151231257827e-17 4.3368086899420177e-19 0" quat="0 0.70710678118654746 0 0.70710678118654757"/>
                                                      </body>
                                                      <joint name="vertebra_C17_extend" class="caudal_extend" pos="0.0035962073049271371 0 9.2628393262655162e-06" axis="-0 1 0" range="-0.26179938779914941 0.26179938779914941"/>
                                                      <geom name="vertebra_C17_collision" class="collision_primitive" size="0.00098037337884306899 0.004654210468288511 0.0035962192341685299" density="2000.0" pos="5.5511151231257827e-17 4.3368086899420177e-19 0" quat="0 0.70710678118654746 0 0.70710678118654757"/>
                                                    </body>
                                                    <geom name="vertebra_C16_collision" class="collision_primitive" size="0.0011268686503171921 0.0043956402514595538 0.0038668927736580372" density="2000.0" pos="5.5511151231257827e-17 0 0" quat="0 0.70710678118654746 0 0.70710678118654757"/>
                                                  </body>
                                                  <joint name="vertebra_C15_bend" class="caudal_bend" pos="0.0038592752082805002 0 0.00018647099914411401" axis="0.048261319178239691 0 -0.99883474362437763" range="-0.26179938779914941 0.26179938779914941"/>
                                                  <geom name="vertebra_C15_collision" class="collision_primitive" size="0.001107205613516271 0.0041370675899088383 0.003863777499645948" density="2000.0" pos="0 -3.4694469519536142e-18 0" quat="-3.0484114965156431e-15 0.69918484550468107 3.117107305228081e-15 0.71494094288730958"/>
                                                </body>
                                                <geom name="vertebra_C14_collision" class="collision_primitive" size="0.001107036438770592 0.0038785065407864749 0.003863667836412787" density="2000.0" pos="-5.5511151231257827e-17 -5.2041704279304213e-18 0" quat="0 0.68661127709289849 0 0.72702472734347823"/>
                                              </body>
                                              <joint name="vertebra_C13_extend" class="caudal_extend" pos="0.004005019444408159 0 0.001505304023099881" axis="-0 1 0" range="-0.26179938779914941 0.26179938779914941"/>
                                              <geom name="vertebra_C13_collision" class="collision_primitive" size="0.0012544237542897461 0.0039599778247065842 0.0042785652913153172" density="2000.0" pos="-1.387778780781446e-17 0 2.1684043449710089e-19" quat="1.8921649036461709e-16 0.62939320922622977 -2.3361814295972612e-16 0.7770869888113604"/>
                                            </body>
                                            <geom name="vertebra_C12_collision" class="collision_primitive" size="0.0014601286500692369 0.004146181046962738 0.0042790831066668034" density="2000.0" pos="0 0 0" quat="1.235560731911126e-17 0.50807932657268906 -7.2884636281232995e-18 0.86131027969567553"/>
                                          </body>
                                          <joint name="vertebra_C11_bend" class="caudal_bend" pos="0.0033221702669597162 0 0.0026975281692883401" axis="0.63034835861330107 0 -0.77631240283375424" range="-0.26179938779914941 0.26179938779914941"/>
                                          <geom name="vertebra_C11_collision" class="collision_primitive" size="0.0014997957274317741 0.0038969448069110508 0.0042794244363903999" density="2000.0" pos="-2.775557561562891e-17 0 0" quat="8.0408085539503005e-17 0.43494441859157318 -3.8839207519475621e-17 0.90045730200606311"/>
                                        </body>
                                        <geom name="vertebra_C10_collision" class="collision_primitive" size="0.0020527174696326261 0.0051967769977636644 0.0039378739893436432" density="2000.0" pos="0 0 -1.7347234759768071e-18" quat="6.6069271991940225e-17 0.40482247803803101 -2.9250288648812828e-17 0.91439529814798803"/>
                                      </body>
                                      <joint name="vertebra_C9_extend" class="caudal_extend" pos="0.0025285567948959962 0 0.003018224679991213" axis="-0 1 0" range="-0.26179938779914941 0.26179938779914941"/>
                                      <geom name="vertebra_C9_collision" class="collision_primitive" size="0.001878352090716362 0.0044948977301828563 0.0039374204352498046" density="2000.0" pos="0 0 -3.4694469519536142e-18" quat="0.93393633089552841 -2.1886851297021869e-17 0.35743940721945872 5.718710691193161e-17"/>
                                    </body>
                                    <geom name="vertebra_C8_collision" class="collision_primitive" size="0.0018094909843057391 0.003957028646254912 0.0039368746802210808" density="2000.0" pos="0 0 -3.4694469519536142e-18" quat="0.95575629612546076 -1.8012083974514359e-17 0.29415965463764848 5.8523194440748775e-17"/>
                                  </body>
                                  <joint name="vertebra_C7_bend" class="caudal_bend" pos="0.0018574175338317109 0 0.0032601272369241988" axis="0.86887528707368111 0 -0.49503104499882472" range="-0.26179938779914941 0.26179938779914941"/>
                                  <geom name="vertebra_C7_collision" class="collision_primitive" size="0.001954166125506163 0.0046388986520469189 0.003752123331651092" density="2000.0" pos="0 0 0" quat="-0.95871816238736907 -0.028643871421635381 -0.2629262253293439 0.10444526687519259"/>
                                </body>
                                <geom name="vertebra_C6_collision" class="collision_primitive" size="0.0023094786331057551 0.0044417925528250626 0.0039176340214908123" density="2000.0" pos="0 0 -6.9388939039072284e-18" quat="-0.9684724633255426 -0.020165366545190799 -0.2338356379719502 0.083518502060948033"/>
                              </body>
                              <joint name="vertebra_C5_extend" class="caudal_extend" pos="0.0020122482295807328 0 0.0028950637724637299" axis="-0 1 0" range="-0.26179938779914941 0.26179938779914941"/>
                              <geom name="vertebra_C5_collision" class="collision_primitive" size="0.0027271977625787261 0.0037766372552141552 0.0035256966948509221" density="2000.0" pos="0 0 0" quat="0.95955512298200196 -1.7238177888175469e-17 0.28152080910475341 5.8755805498267679e-17"/>
                            </body>
                            <geom name="vertebra_C4_collision" class="collision_primitive" size="0.0039916958659887312 0.0038516992935910821 0.0042605199851095676" density="2000.0" pos="0 0 -6.9388939039072284e-18" quat="0.6698964656770412 0.22635972537845331 0.22635972537845331 0.6698964656770412"/>
                          </body>
                          <joint name="vertebra_C3_bend" class="caudal_bend" pos="0.0028146329163340751 0 0.003504352837554861" axis="0.77965718635053138 0 -0.6262065727633116" range="-0.26179938779914941 0.26179938779914941"/>
                          <geom name="vertebra_C3_collision" class="collision_primitive" size="0.0047375869005918496 0.0040974398143589497 0.0044947355054318896" density="2000.0" pos="0 0 6.9388939039072284e-18" quat="0.658413368499565 0.25786010971272011 0.25786010971272011 0.658413368499565"/>
                        </body>
                        <geom name="vertebra_C2_collision" class="collision_primitive" size="0.0050162198022007942 0.003506151144392788 0.0052641532383859158" density="2000.0" pos="0 0 0" quat="0.61659450065834553 0.34613757634484821 0.34613757634484821 0.61659450065834553"/>
                      </body>
                      <joint name="vertebra_C1_extend" class="caudal_extend" pos="0.0043423205380006616 0 0.0032675176492370961" axis="0 1 0" range="-0.26179938779914941 0.26179938779914941"/>
                      <geom name="vertebra_C1_collision" class="collision_primitive" size="0.0065789960324764253 0.0023704245686531071 0.0054343738593161106" density="2000.0" pos="0 -3.388131789017201e-21 0" quat="0.57724085518430246 0.3506607415056362 0.32402767637757213 0.66244705781984103"/>
                    </body>
                  </body>
                </body>
                <joint name="vertebra_5_bend" class="lumbar_bend" axis="0 0 1"/>
              </body>
              <joint name="vertebra_4_extend" class="lumbar_extend" axis="0 1 0"/>
            </body>
            <joint name="vertebra_3_twist" class="lumbar_twist" axis="1 0 0"/>
          </body>
          <joint name="vertebra_2_bend" class="lumbar_bend" axis="0 0 1"/>
        </body>
        <joint name="vertebra_1_extend" class="lumbar_extend" axis="0 1 0"/>
      </body>
      <body name="vertebra_cervical_5" pos="0.033791542655575157 1.442212667144492e-05 -0.0012198962321762761">
        <geom name="vertebra_cervical_5_collision" class="nonself_collision_primitive" type="sphere" size="0.0089999999999999993" density="300.0"/>
        <body name="vertebra_cervical_4" pos="0.0029378543903067632 -1.465240208179275e-05 0.00098728901693379001">
          <geom name="vertebra_cervical_4_collision" class="nonself_collision_primitive" type="sphere" size="0.0083999999999999995" density="300.0"/>
          <body name="vertebra_cervical_3" pos="0.0026222921843344631 1.4733586045965581e-10 0.001148203395641312">
            <geom name="vertebra_cervical_3_collision" class="nonself_collision_primitive" type="sphere" size="0.0077999999999999988" density="300.0"/>
            <body name="vertebra_cervical_2" pos="0.0023170244620595031 1.565828927548445e-10 0.0010667830282407309">
              <geom name="vertebra_cervical_2_collision" class="nonself_collision_primitive" type="sphere" size="0.0071999999999999981" density="300.0"/>
              <body name="vertebra_cervical_1" pos="0.0021676971140992818 5.5147898062010778e-10 0.0011403335697726671">
                <geom name="vertebra_cervical_1_collision" class="nonself_collision_primitive" type="sphere" size="0.0065999999999999982" density="300.0"/>
                <body name="vertebra_axis" pos="0.0022955081282277768 -2.1422566926254879e-06 0.002080317812255511">
                  <geom name="vertebra_axis_collision" class="nonself_collision_primitive" type="sphere" size="0.0059999999999999984" density="300.0"/>
                  <body name="vertebra_atlant" pos="0.0029904660477787638 2.142664924982078e-06 0.001670188692493371">
                    <geom name="vertebra_atlant_collision" class="nonself_collision_primitive" type="sphere" size="0.0053999999999999994" density="300.0"/>
                    <joint name="vertebra_atlant_extend" class="cervical_extend" pos="2.7405829199983609e-05 -4.9553778337723157e-08 -0.00021152928958272321" axis="0 1 0"/>
                    <body name="skull" pos="0.028651004011720171 4.604332577304655e-09 0.002159158385109813">
                      <geom name="skull_0_collision" class="collision_primitive" type="ellipsoid" size="0.02 0.014999999999999999 0.01" pos="-0.01 0 0.001" euler="0 0.17453292519943289 0"/>
                      <geom name="skull_0b_collision" class="collision_primitive" type="ellipsoid" size="0.02 0.014999999999999999 0.01" density="1.0" pos="-0.01 0 0.0040000000000000001" euler="0 0.17453292519943289 0"/>
                      <geom name="skull_F_collision" class="collision_primitive" type="ellipsoid" size="0.0065000000000000006 0.0080000000000000002 0.02" pos="0.016 0 -0.001" euler="0 1.919862177193763 0"/>
                      <geom name="skull_Fb_collision" class="collision_primitive" type="ellipsoid" size="0.0065000000000000006 0.0080000000000000002 0.02" density="1.0" pos="0.016 0 0.002" euler="0 1.919862177193763 0"/>
                      <geom name="skull_L_collision" class="collision_primitive" type="ellipsoid" size="0.0065000000000000006 0.012 0.014" pos="0.0060000000000000001 0.005000000000000001 -0.001" euler="0 1.919862177193763 0"/>
                      <geom name="eye_L_collision" class="collision_primitive" type="sphere" group="1" size="0.0040000000000000001 0.0040000000000000001 0.0040000000000000001" rgba="0 0 0 1" pos="0.001 0.0115 0.0025000000000000001"/>
                      <geom name="skull_R_collision" class="collision_primitive" type="ellipsoid" size="0.0065000000000000006 0.012 0.014" pos="0.0060000000000000001 -0.005000000000000001 -0.001" euler="0 1.919862177193763 0"/>
                      <geom name="eye_R_collision" class="collision_primitive" type="sphere" group="1" size="0.0040000000000000001 0.0040000000000000001 0.0040000000000000001" rgba="0 0 0 1" pos="0.001 -0.0115 0.0025000000000000001"/>
                      <geom name="skull_P0_collision" class="collision_primitive" type="box" size="0.0060000000000000001 0.0056000000000000008 0.0016000000000000001" pos="0.002 0 -0.007000000000000001"/>
                      <geom name="skull_P1_collision" class="collision_primitive" type="box" size="0.0040000000000000001 0.0035999999999999999 0.0011999999999999999" pos="0.007000000000000001 0 -0.007000000000000001"/>
                      <geom name="skull_P2_collision" class="collision_primitive" type="box" size="0.001 0.0030000000000000001 0.00080000000000000004" pos="0.0095000000000000015 0 -0.007000000000000001"/>
                      <geom name="skull_T0_collision" class="collision_primitive" type="ellipsoid" size="0.005000000000000001 0.0060000000000000001 0.0040000000000000001" pos="0.033000000000000002 0 -0.0080000000000000002" euler="0 0.52359877559829882 0"/>
                      <geom name="skull_T1_collision" class="collision_primitive" type="ellipsoid" group="1" size="0.002 0.0015 0.007000000000000001" rgba="1 1 1 1" pos="0.031 0.001 -0.014999999999999999" euler="0 0.52359877559829882 0"/>
                      <geom name="skull_T2_collision" class="collision_primitive" type="ellipsoid" group="1" size="0.002 0.0015 0.007000000000000001" rgba="1 1 1 1" pos="0.031 -0.001 -0.014999999999999999" euler="0 0.52359877559829882 0"/>
                      <joint name="atlas" class="atlas" pos="-0.02843583549004804 0 0"/>
                      <site name="head" class="sensor" type="box" size="0.002 0.002 0.002"/>
                      <camera name="egocentric" fovy="80.0" pos="0.01 0 0.0050000000000000001" euler="0 -1.570796326794897 -1.570796326794897"/>
                      <body name="jaw" pos="0.00050000000000000001 -1.7407750107964681e-08 -0.02" euler="0 0.26179938779914941 0">
                        <geom name="jaw_back_collision" class="collision_primitive" type="ellipsoid" size="0.010999999999999999 0.012 0.007000000000000001" pos="-0.012 0 0.0025000000000000001" euler="0 0.95993108859688125 0"/>
                        <geom name="jaw_F_collision" class="collision_primitive" type="ellipsoid" size="0.0030000000000000001 0.0060000000000000001 0.012" pos="0.0030000000000000001 0 -0.0060000000000000001" euler="0 1.8325957145940459 0"/>
                        <geom name="jaw_L_collision" class="collision_primitive" type="ellipsoid" size="0.0089999999999999993 0.0035000000000000009 0.016" pos="-0.0060000000000000001 0.0089999999999999993 0.001" euler="-0.69813170079773179 2.1816615649929121 0.52359877559829882"/>
                        <geom name="jaw_R_collision" class="collision_primitive" type="ellipsoid" size="0.0089999999999999993 0.0035000000000000009 0.016" pos="-0.0060000000000000001 -0.0089999999999999993 0.001" euler="0.69813170079773179 2.1816615649929121 -0.52359877559829882"/>
                        <geom name="jaw_T0_collision" class="collision_primitive" type="ellipsoid" size="0.0030000000000000001 0.0030000000000000001 0.0060000000000000001" pos="0.014 0 -0.007000000000000001" euler="0 1.2217304763960311 0"/>
                        <geom name="jaw_T1_collision" class="collision_primitive" type="ellipsoid" group="1" size="0.002 0.0011999999999999999 0.007000000000000001" rgba="1 1 1 1" pos="0.019 0.001 -0.005000000000000001" euler="0 1.134464013796314 0"/>
                        <geom name="jaw_T2_collision" class="collision_primitive" type="ellipsoid" group="1" size="0.002 0.0011999999999999999 0.007000000000000001" rgba="1 1 1 1" pos="0.019 -0.001 -0.005000000000000001" euler="0 1.134464013796314 0"/>
                        <geom name="jaw_P0_collision" class="collision_primitive" type="box" size="0.0060000000000000001 0.0056000000000000008 0.0016000000000000001" pos="-0.0030000000000000001 0 0.001" euler="0 0.95993108859688125 0"/>
                        <geom name="jaw_P1_collision" class="collision_primitive" type="box" size="0.0040000000000000001 0.0044000000000000003 0.001" pos="0 0 -0.0011999999999999999" euler="0 0.52359877559829882 0"/>
                        <geom name="jaw_P2_collision" class="collision_primitive" type="box" size="0.0040000000000000001 0.0035999999999999999 0.001" pos="0.0030000000000000001 0 -0.0028" euler="0 0.43633231299858238 0"/>
                        <geom name="jaw_P3_collision" class="collision_primitive" type="box" size="0.0030000000000000001 0.0025999999999999999 0.00060000000000000006" pos="0.0051999999999999998 0 -0.0035000000000000009" euler="0 0.26179938779914941 0"/>
                        <joint name="mandible" class="mandible" pos="-0.018499999999999999 0 0.0040000000000000001" axis="0 1 0"/>
                      </body>
                    </body>
                  </body>
                  <joint name="vertebra_axis_twist" class="cervical_twist" pos="9.9439267225693242e-05 7.3323041593157166e-08 -0.00026762400899821309" axis="0.74098459448325726 -0.00069151539353932078 0.6715216694529994"/>
                </body>
                <joint name="vertebra_cervical_1_bend" class="cervical_bend" pos="2.7469839671064701e-05 -2.2175703241969479e-11 -0.0002637692890460073" axis="-0.46556749786463181 0 0.88501237558127699"/>
              </body>
              <joint name="vertebra_cervical_2_extend" class="cervical_extend" pos="1.2951560981522581e-05 -5.7953729860696879e-12 -0.00025387484726577692" axis="0 1 0"/>
            </body>
            <joint name="vertebra_cervical_3_twist" class="cervical_twist" pos="8.1975708702249013e-06 -4.86590177453699e-12 -0.00025442947362712192" axis="0.91603535672916836 5.1468275847153093e-08 0.40109752582391073"/>
          </body>
          <joint name="vertebra_cervical_4_bend" class="cervical_bend" pos="-1.5375952702610769e-05 4.7972607130889212e-07 -0.00027279087898873908" axis="-0.31854757960001961 0 0.94789508360576713"/>
        </body>
        <joint name="vertebra_cervical_5_extend" class="cervical_extend" pos="-0.00019345864674152679 -3.9985802498100721e-07 -0.0002296866127457893" axis="0 1 0"/>
      </body>
      <body name="scapula_L" pos="0.0080000000000000002 0.002 0.014">
        <joint name="scapula_L_supinate" class="scapula_supinate" pos="0 -0.005000000000000001 0" axis="-0 -0 1"/>
        <joint name="scapula_L_abduct" class="scapula_abduct" pos="0 -0.005000000000000001 -0.01" axis="1 -0 -0"/>
        <joint name="scapula_L_extend" class="scapula_extend" pos="0 0 0" axis="0.29999999999999999 1 0"/>
        <site name="shoulder_L" size="0.002" pos="0.035000000000000003 0.012 -0.031"/>
        <body name="upper_arm_L" pos="0.035000000000000003 0.012 -0.031">
          <joint name="shoulder_L" class="shoulder" axis="0 1 0"/>
          <joint name="shoulder_sup_L" class="shoulder_sup" axis="0 0 -1"/>
          <site name="elbow_L" type="cylinder" size="0.00060000000000000006 0.0040000000000000001" pos="-0.016311817434811103 0.010602681332627217 -0.022836544408735542" zaxis="0 1 0.20000000000000001"/>
          <body name="lower_arm_L" pos="-0.016311817434811103 0.010602681332627217 -0.022836544408735542">
            <joint name="elbow_L" class="elbow" axis="0 1 0.20000000000000001"/>
            <site name="wrist_L" type="cylinder" size="0.00080000000000000004 0.0033999999999999998" pos="0.020045095656359726 0.011692972466209841 -0.01837467101832975" zaxis="0 1 0"/>
            <body name="hand_L" pos="0.020045095656359726 0.011692972466209841 -0.01837467101832975">
              <joint name="wrist_L" class="wrist" axis="0.59999999999999998 -1 0"/>
              <geom name="hand_L_collision" class="collision_primitive_paw" type="ellipsoid" size="0.0053055571027190692 0.0030317469158394677 0.0018190481495036805" pos="0.0015158734579197339 0.00075793672895986693 -0.004547620373759202" euler="-0.69813170079773179 0.87266462599716477 0.78539816339744828"/>
              <site name="finger_L" type="cylinder" size="0.00060000000000000006 0.005000000000000001" pos="0.0030317469158394677 0.0015158734579197339 -0.0083373040185585369" zaxis="-0.20000000000000001 1 0"/>
              <body name="finger_L" pos="0.0030317469158394677 0.0015158734579197339 -0.0083373040185585369">
                <joint name="finger_L" class="finger" axis="-0.5 1 0"/>
                <geom name="finger_L0_collision" class="collision_primitive_paw" size="0.0015158734579197339 0.002652778551359535" pos="0.0049265887382391356 -0.00075793672895986693 0" euler="1.570796326794897 -1.308996938995747 0"/>
                <geom name="finger_L1_collision" class="collision_primitive_paw" size="0.0015158734579197339 0.0030317469158394677" pos="0.004547620373759202 0.0018948418223996674 0" euler="1.570796326794897 -1.099557428756428 0"/>
                <geom name="finger_L2_collision" class="collision_primitive_paw" size="0.0015158734579197339 0.002652778551359535" pos="0.002652778551359535 0.0037896836447993357 0" euler="1.570796326794897 -0.95993108859688125 0"/>
                <site name="palm_L" class="sensor" type="box" size="0.0040000000000000001 0.0040000000000000001 0.002" pos="0.0060000000000000001 0.0030000000000000001 -0.002" euler="0 0 0.48869219055841229"/>
              </body>
            </body>
            <geom name="radius_L_collision" class="collision_primitive" size="0.0028397218846509609 0.012110578625717336" pos="0.010675907786454922 0.0063567926942646102 -0.011344803054541136" quat="0.023764932308462921 0.79177214415182184 0.42322934679317159 0.43978292344135678"/>
            <geom name="ulna_L_collision" class="collision_primitive" size="0.0033408492760599543 0.010022547828179863" pos="0.0062631042370223733 0.0046324637027568864 -0.0088056274040260157" quat="0.012822444520418631 0.74462498727826065 0.47760656071953278 0.46611284727523911"/>
          </body>
          <geom name="humerus_L_collision" class="collision_primitive" size="0.0065247269739244409 0.013049453947848882" pos="-0.0079283390273695766 0.0059262582492211587 -0.012269644440841653" quat="0.47256099918016298 0.34500828054201771 0.00070160501549135191 0.8109592444517103"/>
        </body>
        <geom name="scapula_L_collision" class="nonself_collision_primitive" type="ellipsoid" size="0.0050053708255290994 0.014631827920675281 0.024311044067144391" pos="0.021427588427603231 0.010532825219649501 -0.018572588405703559" quat="0.18441940626963749 0.76922228553766514 0.47403228455170038 0.38675567381237091"/>
      </body>
      <body name="scapula_R" pos="0.0080000000000000002 -0.002 0.014">
        <joint name="scapula_R_supinate" class="scapula_supinate" pos="0 0.005000000000000001 0" axis="0 0 -1"/>
        <joint name="scapula_R_abduct" class="scapula_abduct" pos="0 0.005000000000000001 -0.01" axis="-1 0 0"/>
        <joint name="scapula_R_extend" class="scapula_extend" pos="0 0 0" axis="-0.29999999999999999 1 0"/>
        <site name="shoulder_R" size="0.002" pos="0.035000000000000003 -0.012 -0.031"/>
        <body name="upper_arm_R" pos="0.035000000000000003 -0.012 -0.031">
          <joint name="shoulder_R" class="shoulder" axis="0 1 0"/>
          <joint name="shoulder_sup_R" class="shoulder_sup" axis="-0 -0 1"/>
          <site name="elbow_R" type="cylinder" size="0.00060000000000000006 0.0040000000000000001" pos="-0.016311817434811103 -0.010602681332627217 -0.022836544408735542" zaxis="0 1 -0.20000000000000001"/>
          <body name="lower_arm_R" pos="-0.016311817434811103 -0.010602681332627217 -0.022836544408735542">
            <joint name="elbow_R" class="elbow" axis="0 1 -0.20000000000000001"/>
            <site name="wrist_R" type="cylinder" size="0.00080000000000000004 0.0033999999999999998" pos="0.020045095656359726 -0.011692972466209841 -0.01837467101832975" zaxis="0 1 0"/>
            <body name="hand_R" pos="0.020045095656359726 -0.011692972466209841 -0.01837467101832975">
              <joint name="wrist_R" class="wrist" axis="-0.59999999999999998 -1 0"/>
              <geom name="hand_R_collision" class="collision_primitive_paw" type="ellipsoid" size="0.0053055571027190692 0.0030317469158394677 0.0018190481495036805" pos="0.0015158734579197339 -0.00075793672895986693 -0.004547620373759202" euler="0.69813170079773179 0.87266462599716477 -0.78539816339744828"/>
              <site name="finger_R" type="cylinder" size="0.00060000000000000006 0.005000000000000001" pos="0.0030317469158394677 -0.0015158734579197339 -0.0083373040185585369" zaxis="0.20000000000000001 1 0"/>
              <body name="finger_R" pos="0.0030317469158394677 -0.0015158734579197339 -0.0083373040185585369">
                <joint name="finger_R" class="finger" axis="0.5 1 0"/>
                <geom name="finger_R0_collision" class="collision_primitive_paw" size="0.0015158734579197339 0.002652778551359535" pos="0.0049265887382391356 0.00075793672895986693 0" euler="1.570796326794897 1.308996938995747 0"/>
                <geom name="finger_R1_collision" class="collision_primitive_paw" size="0.0015158734579197339 0.0030317469158394677" pos="0.004547620373759202 -0.0018948418223996674 0" euler="1.570796326794897 1.099557428756428 0"/>
                <geom name="finger_R2_collision" class="collision_primitive_paw" size="0.0015158734579197339 0.002652778551359535" pos="0.002652778551359535 -0.0037896836447993357 0" euler="1.570796326794897 0.95993108859688125 0"/>
                <site name="palm_R" class="sensor" type="box" size="0.0040000000000000001 0.0040000000000000001 0.002" pos="0.0060000000000000001 -0.0030000000000000001 -0.002" euler="0 0 -0.48869219055841229"/>
              </body>
            </body>
            <geom name="radius_R_collision" class="collision_primitive" size="0.0028397218846509609 0.012110578625717336" pos="0.010675914022418024 -0.0063572028323562466 -0.011344807731243864" quat="0.43978285859011762 0.42323047325609903 0.79177155870747651 0.023765576358593481"/>
            <geom name="ulna_R_collision" class="collision_primitive" size="0.0033408492760599543 0.010022547828179863" pos="0.0062631066191319506 -0.0046328720559751131 -0.0088056274549155183" quat="0.46611278282571561 0.47760677953250608 0.74462488546938377 0.01282254930824632"/>
          </body>
          <geom name="humerus_R_collision" class="collision_primitive" size="0.0065247269739244409 0.013049453947848882" pos="-0.0079283364056461896 -0.0059266357275257744 -0.012269642325501833" quat="0.81095939353104862 0.00070139480829139946 0.34500827950404478 0.47256074441571583"/>
        </body>
        <geom name="scapula_R_collision" class="nonself_collision_primitive" type="ellipsoid" size="0.0050053702667355532 0.014631831273436551 0.024311039596796039" pos="0.021427585595737229 -0.01053328691142344 -0.018572586131841391" quat="0.38675569721296882 0.47403213120406879 0.76922234964236824 0.1844194839763772"/>
      </body>
    </body>
  </worldbody>
  <contact>
    <exclude name="pelvis:vertebra_C3" body1="pelvis" body2="vertebra_C3"/>
    <exclude name="pelvis:vertebra_C4" body1="pelvis" body2="vertebra_C4"/>
    <exclude name="vertebra_axis:skull" body1="vertebra_axis" body2="skull"/>
  </contact>
  <tendon>
    <fixed name="lumbar_extend" class="lumbar_extend">
      <joint joint="vertebra_1_extend" coef="0.611232384148"/>
      <joint joint="vertebra_4_extend" coef="0.388767615852"/>
    </fixed>
    <fixed name="lumbar_bend" class="lumbar_bend">
      <joint joint="vertebra_2_bend" coef="0.673440169021"/>
      <joint joint="vertebra_5_bend" coef="0.326559830979"/>
    </fixed>
    <fixed name="lumbar_twist" class="lumbar_twist">
      <joint joint="vertebra_3_twist" coef="0.567275016346"/>
      <joint joint="vertebra_6_twist" coef="0.432724983654"/>
    </fixed>
    <fixed name="cervical_extend" class="cervical_extend">
      <joint joint="vertebra_cervical_5_extend" coef="0.341713547174"/>
      <joint joint="vertebra_cervical_2_extend" coef="0.332408292936"/>
      <joint joint="vertebra_atlant_extend" coef="0.32587815989"/>
    </fixed>
    <fixed name="cervical_bend" class="cervical_bend">
      <joint joint="vertebra_cervical_4_bend" coef="0.50743949691"/>
      <joint joint="vertebra_cervical_1_bend" coef="0.49256050309"/>
    </fixed>
    <fixed name="cervical_twist" class="cervical_twist">
      <joint joint="vertebra_cervical_3_twist" coef="0.496142185731"/>
      <joint joint="vertebra_axis_twist" coef="0.503857814269"/>
    </fixed>
    <fixed name="caudal_extend" class="caudal_extend">
      <joint joint="vertebra_C1_extend" coef="0.427378558354"/>
      <joint joint="vertebra_C5_extend" coef="0.255659487498"/>
      <joint joint="vertebra_C9_extend" coef="0.162015531448"/>
      <joint joint="vertebra_C13_extend" coef="0.0908820320559"/>
      <joint joint="vertebra_C17_extend" coef="0.0419255178006"/>
      <joint joint="vertebra_C21_extend" coef="0.0165806599147"/>
      <joint joint="vertebra_C25_extend" coef="0.00419149795848"/>
      <joint joint="vertebra_C29_extend" coef="0.00136671497022"/>
    </fixed>
    <fixed name="caudal_bend" class="caudal_bend">
      <joint joint="vertebra_C3_bend" coef="0.465959582647"/>
      <joint joint="vertebra_C7_bend" coef="0.208208889814"/>
      <joint joint="vertebra_C11_bend" coef="0.156709309744"/>
      <joint joint="vertebra_C15_bend" coef="0.105497877966"/>
      <joint joint="vertebra_C19_bend" coef="0.0454826232883"/>
      <joint joint="vertebra_C23_bend" coef="0.0146832624497"/>
      <joint joint="vertebra_C27_bend" coef="0.00345845409169"/>
    </fixed>
  </tendon>
  <actuator>
    <general name="lumbar_extend" forcerange="-20 20" tendon="lumbar_extend" dyntype="filter" biastype="affine" dynprm="0.040000000000000001" gainprm="7.8539816339744828" biasprm="-2.617993877991494 -20"/>
    <general name="lumbar_bend" forcerange="-20 20" tendon="lumbar_bend" dyntype="filter" biastype="affine" dynprm="0.040000000000000001" gainprm="10.471975511965979" biasprm="0 -20"/>
    <general name="lumbar_twist" forcerange="-20 20" tendon="lumbar_twist" dyntype="filter" biastype="affine" dynprm="0.040000000000000001" gainprm="10.471975511965979" biasprm="0 -20"/>
    <general name="cervical_extend" forcerange="-20 20" tendon="cervical_extend" dyntype="filter" biastype="affine" dynprm="0.040000000000000001" gainprm="10.181087303300259" biasprm="2.0362174606600512 -20"/>
    <general name="cervical_bend" forcerange="-20 20" tendon="cervical_bend" dyntype="filter" biastype="affine" dynprm="0.040000000000000001" gainprm="12.217304763960311" biasprm="0 -20"/>
    <general name="cervical_twist" forcerange="-20 20" tendon="cervical_twist" dyntype="filter" biastype="affine" dynprm="0.040000000000000001" gainprm="12.217304763960311" biasprm="0 -20"/>
    <general name="caudal_extend" forcerange="-0.10000000000000001 0.10000000000000001" tendon="caudal_extend" dyntype="filter" biastype="affine" dynprm="0.040000000000000001" gainprm="0.026179938779914948" biasprm="0 -0.10000000000000001"/>
    <general name="caudal_bend" forcerange="-0.10000000000000001 0.10000000000000001" tendon="caudal_bend" dyntype="filter" biastype="affine" dynprm="0.040000000000000001" gainprm="0.026179938779914941" biasprm="0 -0.10000000000000001"/>
    <general name="hip_L_supinate" forcerange="-0.14999999999999999 0.14999999999999999" joint="hip_L_supinate" dyntype="filter" biastype="affine" dynprm="0.040000000000000001" gainprm="0.1570796326794896" biasprm="0 -0.29999999999999999"/>
    <general name="hip_L_abduct" forcerange="-0.14999999999999999 0.14999999999999999" joint="hip_L_abduct" dyntype="filter" biastype="affine" dynprm="0.040000000000000001" gainprm="0.2094395102393195" biasprm="0.10471975511965979 -0.29999999999999999"/>
    <general name="hip_L_extend" forcerange="-0.14999999999999999 0.14999999999999999" joint="hip_L_extend" dyntype="filter" biastype="affine" dynprm="0.040000000000000001" gainprm="0.39269908169872408" biasprm="-0.078539816339744842 -0.29999999999999999"/>
    <general name="knee_L" forcerange="-0.074999999999999997 0.074999999999999997" joint="knee_L" dyntype="filter" biastype="affine" dynprm="0.040000000000000001" gainprm="0.20682151636132801" biasprm="0.02356194490192345 -0.14999999999999999"/>
    <general name="ankle_L" forcerange="-0.050000000000000003 0.050000000000000003" joint="ankle_L" dyntype="filter" biastype="affine" dynprm="0.040000000000000001" gainprm="0.076794487087750496" biasprm="0.062831853071795868 -0.10000000000000001"/>
    <general name="toe_L" forcerange="-0.0025000000000000001 0.0025000000000000001" joint="toe_L" dyntype="filter" biastype="affine" dynprm="0.040000000000000001" gainprm="0.0021816615649929119" biasprm="0.0021816615649929119 -0.0050000000000000001"/>
    <general name="hip_R_supinate" forcerange="-0.14999999999999999 0.14999999999999999" joint="hip_R_supinate" dyntype="filter" biastype="affine" dynprm="0.040000000000000001" gainprm="0.1570796326794896" biasprm="0 -0.29999999999999999"/>
    <general name="hip_R_abduct" forcerange="-0.14999999999999999 0.14999999999999999" joint="hip_R_abduct" dyntype="filter" biastype="affine" dynprm="0.040000000000000001" gainprm="0.2094395102393195" biasprm="0.10471975511965979 -0.29999999999999999"/>
    <general name="hip_R_extend" forcerange="-0.14999999999999999 0.14999999999999999" joint="hip_R_extend" dyntype="filter" biastype="affine" dynprm="0.040000000000000001" gainprm="0.39269908169872408" biasprm="-0.078539816339744842 -0.29999999999999999"/>
    <general name="knee_R" forcerange="-0.074999999999999997 0.074999999999999997" joint="knee_R" dyntype="filter" biastype="affine" dynprm="0.040000000000000001" gainprm="0.20682151636132801" biasprm="0.02356194490192345 -0.14999999999999999"/>
    <general name="ankle_R" forcerange="-0.050000000000000003 0.050000000000000003" joint="ankle_R" dyntype="filter" biastype="affine" dynprm="0.040000000000000001" gainprm="0.076794487087750496" biasprm="0.062831853071795868 -0.10000000000000001"/>
    <general name="toe_R" forcerange="-0.0025000000000000001 0.0025000000000000001" joint="toe_R" dyntype="filter" biastype="affine" dynprm="0.040000000000000001" gainprm="0.0021816615649929119" biasprm="0.0021816615649929119 -0.0050000000000000001"/>
    <general name="atlas" forcerange="-0.025000000000000001 0.025000000000000001" joint="atlas" dyntype="filter" biastype="affine" dynprm="0.040000000000000001" gainprm="0.021816615649929118" biasprm="0.017453292519943299 -0.050000000000000003"/>
    <general name="mandible" forcerange="-0.025000000000000001 0.025000000000000001" joint="mandible" dyntype="filter" biastype="affine" dynprm="0.040000000000000001" gainprm="0.01396263401595464" biasprm="-0.00087266462599716599 -0.050000000000000003"/>
    <general name="scapula_L_supinate" forcerange="-0.25 0.25" joint="scapula_L_supinate" dyntype="filter" biastype="affine" dynprm="0.040000000000000001" gainprm="0.04799655442984406" biasprm="0.039269908169872407 -0.5"/>
    <general name="scapula_L_abduct" forcerange="-0.25 0.25" joint="scapula_L_abduct" dyntype="filter" biastype="affine" dynprm="0.040000000000000001" gainprm="0.1308996938995747" biasprm="0 -0.5"/>
    <general name="scapula_L_extend" forcerange="-0.25 0.25" joint="scapula_L_extend" dyntype="filter" biastype="affine" dynprm="0.040000000000000001" gainprm="0.017453292519943299" biasprm="0 -0.5"/>
    <general name="shoulder_L" forcerange="-0.14999999999999999 0.14999999999999999" joint="shoulder_L" dyntype="filter" biastype="affine" dynprm="0.040000000000000001" gainprm="0.3272492347489368" biasprm="-0.065449846949787366 -0.29999999999999999"/>
    <general name="shoulder_sup_L" forcerange="-0.14999999999999999 0.14999999999999999" joint="shoulder_sup_L" dyntype="filter" biastype="affine" dynprm="0.040000000000000001" gainprm="0.12566370614359171" biasprm="0.1099557428756428 -0.29999999999999999"/>
    <general name="elbow_L" forcerange="-0.14999999999999999 0.14999999999999999" joint="elbow_L" dyntype="filter" biastype="affine" dynprm="0.040000000000000001" gainprm="0.2748893571891069" biasprm="-0.1178097245096173 -0.29999999999999999"/>
    <general name="wrist_L" forcerange="-0.050000000000000003 0.050000000000000003" joint="wrist_L" dyntype="filter" biastype="affine" dynprm="0.040000000000000001" gainprm="0.1221730476396031" biasprm="0.087266462599716474 -0.10000000000000001"/>
    <general name="finger_L" forcerange="-0.025000000000000001 0.025000000000000001" joint="finger_L" dyntype="filter" biastype="affine" dynprm="0.040000000000000001" gainprm="0.039269908169872407" biasprm="0.039269908169872407 -0.050000000000000003"/>
    <general name="scapula_R_supinate" forcerange="-0.25 0.25" joint="scapula_R_supinate" dyntype="filter" biastype="affine" dynprm="0.040000000000000001" gainprm="0.04799655442984406" biasprm="0.039269908169872407 -0.5"/>
    <general name="scapula_R_abduct" forcerange="-0.25 0.25" joint="scapula_R_abduct" dyntype="filter" biastype="affine" dynprm="0.040000000000000001" gainprm="0.1308996938995747" biasprm="0 -0.5"/>
    <general name="scapula_R_extend" forcerange="-0.25 0.25" joint="scapula_R_extend" dyntype="filter" biastype="affine" dynprm="0.040000000000000001" gainprm="0.017453292519943299" biasprm="0 -0.5"/>
    <general name="shoulder_R" forcerange="-0.14999999999999999 0.14999999999999999" joint="shoulder_R" dyntype="filter" biastype="affine" dynprm="0.040000000000000001" gainprm="0.3272492347489368" biasprm="-0.065449846949787366 -0.29999999999999999"/>
    <general name="shoulder_sup_R" forcerange="-0.14999999999999999 0.14999999999999999" joint="shoulder_sup_R" dyntype="filter" biastype="affine" dynprm="0.040000000000000001" gainprm="0.12566370614359171" biasprm="0.1099557428756428 -0.29999999999999999"/>
    <general name="elbow_R" forcerange="-0.14999999999999999 0.14999999999999999" joint="elbow_R" dyntype="filter" biastype="affine" dynprm="0.040000000000000001" gainprm="0.2748893571891069" biasprm="-0.1178097245096173 -0.29999999999999999"/>
    <general name="wrist_R" forcerange="-0.050000000000000003 0.050000000000000003" joint="wrist_R" dyntype="filter" biastype="affine" dynprm="0.040000000000000001" gainprm="0.1221730476396031" biasprm="0.087266462599716474 -0.10000000000000001"/>
    <general name="finger_R" forcerange="-0.025000000000000001 0.025000000000000001" joint="finger_R" dyntype="filter" biastype="affine" dynprm="0.040000000000000001" gainprm="0.039269908169872407" biasprm="0.039269908169872407 -0.050000000000000003"/>
  </actuator>
  <sensor>
    <accelerometer name="accelerometer" site="head"/>
    <velocimeter name="velocimeter" site="head"/>
    <gyro name="gyro" site="head"/>
    <touch name="palm_L" site="palm_L"/>
    <touch name="palm_R" site="palm_R"/>
    <touch name="sole_L" site="sole_L"/>
    <touch name="sole_R" site="sole_R"/>
    <subtreelinvel name="torso" body="torso"/>
  </sensor>
  <compiler angle="radian" meshdir="./"/>
</mujoco>
