<mujoco model="rat">
  <size njmax="2000" nconmax="1000"/>
  <visual>
    <quality shadowsize="2048"/>
  </visual>
  <default>
    <mesh scale="1 1 1"/>
    <joint limited="true" solreflimit="0.01 1" solimplimit="0.98999999999999999 0.99990000000000001 0" armature="6e-08" damping="0.0001"/>
    <geom friction="0.69999999999999996 0.0050000000000000001 0.0001" solref="0.0050000000000000001 1"/>
    <site group="3" rgba="0 0 1 1"/>
    <general ctrllimited="true" ctrlrange="-1 1" gainprm="0.01"/>
    <default class="bone">
      <geom contype="0" conaffinity="0" group="0" rgba="0.5 0.5 0.5 1" density="1100.0"/>
    </default>
    <default class="collision">
      <geom contype="1" conaffinity="1" condim="1" group="2"/>
      <default class="collision_primitive">
        <geom type="capsule" group="2" rgba="0 0.5 0.5 1" density="500.0"/>
        <default class="collision_primitive_paw">
          <geom condim="3" priority="1" rgba="0 0.59999999999999998 0.69999999999999996 1" friction="1.5 0.0050000000000000001 0.0001"/>
        </default>
        <default class="nonself_collision_primitive">
          <geom conaffinity="0"/>
        </default>
      </default>
      <default class="lumbar">
        <joint group="3" pos="0.0030000000000000001 0 -0.0030000000000000001" armature="1e-05" damping="0.03"/>
        <general gainprm="0.14999999999999999"/>
        <default class="lumbar_extend">
          <joint stiffness="0.02" range="-0.52359877559829882 0.26179938779914941"/>
          <tendon range="-1 1"/>
          <general gainprm="0.40000000000000002"/>
        </default>
        <default class="lumbar_bend">
          <joint stiffness="0.03" range="-0.52359877559829882 0.52359877559829882"/>
          <tendon range="-1 1"/>
        </default>
        <default class="lumbar_twist">
          <joint stiffness="0.03" range="-0.52359877559829882 0.52359877559829882"/>
          <tendon range="-1 1"/>
        </default>
      </default>
      <default class="cervical">
        <joint group="3" pos="-0.02 0 -0.050000000000000003" stiffness="1.0" armature="0.001" damping="5.0"/>
        <default class="cervical_extend">
          <joint range="-0.40724349213201022 0.6108652381980153"/>
          <tendon range="-1 1"/>
          <general gainprm="0.5"/>
        </default>
        <default class="cervical_bend">
          <joint range="-0.6108652381980153 0.6108652381980153"/>
          <tendon range="-1 1"/>
          <general gainprm="0.5"/>
        </default>
        <default class="cervical_twist">
          <joint range="-0.6108652381980153 0.6108652381980153"/>
          <tendon range="-1 1"/>
          <general gainprm="0.5"/>
        </default>
      </default>
      <default class="atlas">
        <joint axis="0 -1 0" stiffness="0.002" range="-0.087266462599716474 0.78539816339744828" damping="0.002"/>
        <general gainprm="0.025000000000000001"/>
      </default>
      <default class="mandible">
        <joint stiffness="0.002" range="-0.29670597283903599 0.26179938779914941" springref="-0.314159265359" damping="0.002"/>
        <general gainprm="0.025000000000000001"/>
      </default>
      <default class="caudal">
        <joint group="3" stiffness="1e-05" damping="0.01"/>
        <general gainprm="0.0050000000000000001"/>
        <default class="caudal_extend">
          <joint range="-0.1308996938995747 0.1308996938995747"/>
          <tendon range="-0.050000000000000003 0.050000000000000003"/>
        </default>
        <default class="caudal_bend">
          <joint range="-0.14959965017094251 0.14959965017094251"/>
          <tendon range="-0.20000000000000001 0.20000000000000001"/>
        </default>
      </default>
      <default class="hip">
        <joint armature="1e-05" damping="0.02"/>
        <general gainprm="0.14999999999999999"/>
        <default class="hip_supinate">
          <joint range="-0.52359877559829882 0.52359877559829882"/>
        </default>
        <default class="hip_abduct">
          <joint range="-0.3490658503988659 1.0471975511965981"/>
        </default>
        <default class="hip_extend">
          <joint range="-1.570796326794897 1.0471975511965981"/>
          <general gainprm="0.14999999999999999"/>
        </default>
      </default>
      <default class="knee">
        <joint range="-1.2217304763960311 1.5358897417550099" damping="0.005"/>
        <general gainprm="0.074999999999999997"/>
      </default>
      <default class="ankle">
        <joint range="-0.13962634015954639 1.396263401595464" damping="0.003"/>
        <general gainprm="0.050000000000000003"/>
      </default>
      <default class="toe">
        <joint range="0 0.87266462599716477" damping="0.0001"/>
        <general gainprm="0.0025000000000000001"/>
      </default>
      <default class="scapula">
        <joint damping="0.005"/>
        <general gainprm="0.25"/>
        <default class="scapula_supinate">
          <joint pos="0 0.005000000000000001 0" range="-0.017453292519943299 0.17453292519943289"/>
        </default>
        <default class="scapula_abduct">
          <joint pos="0 0.005000000000000001 -0.01" range="-0.26179938779914941 0.26179938779914941"/>
        </default>
        <default class="scapula_extend">
          <joint pos="0 0 0" range="-0.034906585039886591 0.034906585039886591"/>
          <general gainprm="0.25"/>
        </default>
      </default>
      <default class="shoulder">
        <joint range="-1.308996938995747 0.87266462599716477" damping="0.005"/>
        <general gainprm="0.14999999999999999"/>
      </default>
      <default class="shoulder_sup">
        <joint range="-0.05235987755982989 0.78539816339744828" damping="0.005"/>
        <general gainprm="0.14999999999999999"/>
      </default>
      <default class="elbow">
        <joint range="-1.308996938995747 0.52359877559829882" damping="0.003"/>
        <general gainprm="0.14999999999999999"/>
      </default>
      <default class="wrist">
        <joint range="-0.3490658503988659 2.0943951023931948" damping="0.002"/>
        <general gainprm="0.050000000000000003"/>
      </default>
      <default class="finger">
        <joint range="0 1.570796326794897" damping="0.002"/>
        <general gainprm="0.025000000000000001"/>
      </default>
      <default class="sensor">
        <site group="4"/>
      </default>
    </default>
  </default>
  <statistic meansize="0.003"/>
  <asset>
    <texture name="skybox" type="skybox" builtin="gradient" rgb1="0.40000000000000002 0.59999999999999998 0.80000000000000004" rgb2="0 0 0" mark="random" markrgb="1 1 1" width="800" height="800"/>
    <texture name="grid" type="2d" builtin="checker" rgb1="0.10000000000000001 0.20000000000000001 0.29999999999999999" rgb2="0.20000000000000001 0.29999999999999999 0.40000000000000002" mark="edge" markrgb="0.20000000000000001 0.29999999999999999 0.40000000000000002" width="300" height="300"/>
    <material name="grid" texture="grid" texrepeat="1 1" texuniform="true" reflectance="0.2"/>
    <material name="self" rgba="0.69999999999999996 0.5 0.29999999999999999 1"/>
    <material name="self_default" rgba="0.69999999999999996 0.5 0.29999999999999999 1"/>
    <material name="self_highlight" rgba="0 0.5 0.29999999999999999 1"/>
    <material name="effector" rgba="0.69999999999999996 0.40000000000000002 0.20000000000000001 1"/>
    <material name="effector_default" rgba="0.69999999999999996 0.40000000000000002 0.20000000000000001 1"/>
    <material name="effector_highlight" rgba="0 0.5 0.29999999999999999 1"/>
    <material name="decoration" rgba="0.29999999999999999 0.5 0.69999999999999996 1"/>
    <material name="eye" rgba="0 0.20000000000000001 1 1"/>
    <material name="target" rgba="0.59999999999999998 0.29999999999999999 0.29999999999999999 1"/>
    <material name="target_default" rgba="0.59999999999999998 0.29999999999999999 0.29999999999999999 1"/>
    <material name="target_highlight" rgba="0.59999999999999998 0.29999999999999999 0.29999999999999999 0.40000000000000002"/>
    <skin name="skin" file="rat_skin_walker.skn"/>
  </asset>
  <worldbody>
    <body name="torso" pos="0.030995260545782881 2.0585249376514574e-07 0.065089572631199674">
      <light name="light" mode="trackcom" pos="0 0 3"/>
      <camera name="back" mode="trackcom" pos="-1 0 0.5" xyaxes="0 -1 0 1 0 2"/>
      <camera name="side" mode="trackcom" pos="0 -1 0.5" xyaxes="1 0 0 0 1 2"/>
      <camera name="top" mode="trackcom" fovy="100.0" pos="0 0 1" zaxis="0 -0.20000000000000001 1"/>
      <geom name="collision_torso" class="nonself_collision_primitive" type="ellipsoid" size="0.050000000000000003 0.024 0.025999999999999999" density="468.25126000866914" pos="-0.008199999999999999 0 0" euler="0 0.17453292519943289 0"/>
      <body name="vertebra_1" pos="-0.019179443666608526 -1.8803355927589691e-07 0.016846456906490889">
        <geom name="vertebra_1_collision" class="nonself_collision_primitive" type="sphere" size="0.01" pos="0 0 -0.00164"/>
        <body name="vertebra_2" pos="-0.0056297163353177171 2.5948035886584436e-06 0.00053209226987832364">
          <geom name="vertebra_2_collision" class="nonself_collision_primitive" type="sphere" size="0.01" pos="0 0 -0.00164"/>
          <body name="vertebra_3" pos="-0.0065171666725424094 -1.0410628653607658e-05 -9.4672188948204906e-05">
            <geom name="vertebra_3_collision" class="nonself_collision_primitive" type="sphere" size="0.01" pos="0 0 -0.00164"/>
            <body name="vertebra_4" pos="-0.0067777041851870348 8.7461011271628984e-06 -0.0012993147728524747">
              <geom name="vertebra_4_collision" class="nonself_collision_primitive" type="sphere" size="0.01" pos="0 0 -0.00164"/>
              <body name="vertebra_5" pos="-0.0068900665623031019 -6.2043336497232209e-06 -0.0024980649787824548">
                <geom name="vertebra_5_collision" class="nonself_collision_primitive" type="sphere" size="0.01" pos="0 0 -0.00164"/>
                <body name="vertebra_6" pos="-0.0061852844346815122 5.2544421289550478e-06 -0.0036411224530278337">
                  <geom name="vertebra_6_collision" class="nonself_collision_primitive" type="sphere" size="0.01" pos="0 0 -0.00164"/>
                  <joint name="vertebra_6_twist" class="lumbar_twist" axis="1 0 0"/>
                  <body name="pelvis" pos="-0.013071409198843958 3.513221433820909e-06 -0.0081209828297725325">
                    <geom name="collision_pelvis_L" class="nonself_collision_primitive" size="0.012999999999999999 0.021000000000000001 0" density="1548.5773692882858" pos="-0.00081999999999999998 0.0065599999999999999 -0.0057400000000000003" euler="0 0.87266462599716477 0"/>
                    <geom name="collision_pelvis_R" class="nonself_collision_primitive" size="0.012999999999999999 0.021000000000000001 0" density="1548.5773692882858" pos="-0.00081999999999999998 -0.0065599999999999999 -0.0057400000000000003" euler="0 0.87266462599716477 0"/>
                    <geom name="collision_pelvis_gut" class="nonself_collision_primitive" type="ellipsoid" size="0.02 0.02 0.017999999999999999" density="1548.5773692882858" pos="0.020500000000000001 0 -0.016399999999999998" euler="0 -0.52359877559829882 0"/>
                    <site name="hip_L" size="0.0022000000000000001" pos="-0.0048102924167646149 0.011491254106715469 -0.0098878233011272659"/>
                    <site name="hip_R" size="0.0022000000000000001" pos="-0.0048102924167646149 -0.011491254106715469 -0.0098878233011272659"/>
                    <body name="upper_leg_L" pos="-0.0048102924167646149 0.011491254106715469 -0.0098878233011272659">
                      <joint name="hip_L_supinate" class="hip_supinate" axis="-0 -0 1"/>
                      <joint name="hip_L_abduct" class="hip_abduct" axis="1 -0 -0"/>
                      <joint name="hip_L_extend" class="hip_extend" axis="0 1 0"/>
                      <site name="knee_L" type="cylinder" size="0.00060000000000000006 0.0040000000000000001" pos="0.015422645345868605 0.017478998058651083 -0.025704408909781006" zaxis="0 1 0"/>
                      <geom name="upper_leg_L0_collision" class="collision_primitive" size="0.0087424030022309803 0.017484806004461961" density="1561.7555055600315" pos="0.0086025245541952854 0.010753155692744105 -0.012903786831292927" euler="0.6108652381980153 -0.69813170079773179 0"/>
                      <body name="lower_leg_L" pos="0.015422645345868605 0.017478998058651083 -0.025704408909781006">
                        <joint name="knee_L" class="knee" axis="0.5 -1 0"/>
                        <site name="ankle_L" type="cylinder" size="0.00060000000000000006 0.0025999999999999999" pos="-0.03230154033783407 -0.0047270546835854734 -0.022059588523398874" zaxis="0 1 0"/>
                        <body name="foot_L" pos="-0.03230154033783407 -0.0047270546835854734 -0.022059588523398874">
                          <joint name="ankle_L" class="ankle" axis="-0.29999999999999999 1 0"/>
                          <geom name="foot_L_collision" class="collision_primitive_paw" size="0.0032107122078339698 0.012384175658788165" density="2041.159782276932" pos="0.0082744640327606835 0.0022566720089347322 -0.0022566720089347322" euler="1.570796326794897 -1.2217304763960311 0"/>
                          <site name="toe_L" type="cylinder" size="0.00060000000000000006 0.005000000000000001" pos="0.021099943113672619 0.007614327297542728 -0.0027521664930877329" zaxis="0 1 0"/>
                          <body name="toe_L" pos="0.021099943113672619 0.007614327297542728 -0.0027521664930877329">
                            <joint name="toe_L" class="toe" axis="0 1 0"/>
                            <geom name="toe_L0_collision" class="collision_primitive_paw" size="0.0023832084241499803 0.0072532430300216808" pos="0.0084966561208825384 -0.00084966561208825388 0" euler="1.570796326794897 -1.2217304763960311 0"/>
                            <geom name="toe_L1_collision" class="collision_primitive_paw" size="0.0023832084241499803 0.0077713318178803704" pos="0.0080718233148384128 0.0025489968362647614 0" euler="1.570796326794897 -1.2217304763960311 0"/>
                            <geom name="toe_L2_collision" class="collision_primitive_paw" size="0.0023832084241499803 0.0072532430300216808" pos="0.006797324896706031 0.005522826478573651 0" euler="1.570796326794897 -1.2217304763960311 0"/>
                            <site name="sole_L" class="sensor" type="box" size="0.0060000000000000001 0.0040000000000000001 0.002" pos="0.008199999999999999 0.0024599999999999999 -0.00164" euler="0 0 0.3490658503988659"/>
                          </body>
                        </body>
                        <geom name="lower_leg_L_collision" class="collision_primitive" size="0.0065568022516732357 0.019233286604908157" density="1302.8668726714393" pos="-0.012263390469294306 0.00012247924262217714 -0.010718133653039408" quat="0.58439398761405215 0.27858155227390202 0.39004539538183519 0.65478284607542836"/>
                      </body>
                    </body>
                    <body name="upper_leg_R" pos="-0.0048102924167646149 -0.011491254106715469 -0.0098878233011272659">
                      <joint name="hip_R_supinate" class="hip_supinate" axis="0 0 -1"/>
                      <joint name="hip_R_abduct" class="hip_abduct" axis="-1 0 0"/>
                      <joint name="hip_R_extend" class="hip_extend" axis="0 1 0"/>
                      <site name="knee_R" type="cylinder" size="0.00060000000000000006 0.0040000000000000001" pos="0.015422645345868605 -0.017478998058651083 -0.025704408909781006" zaxis="0 1 0"/>
                      <geom name="upper_leg_R0_collision" class="collision_primitive" size="0.0087424030022309803 0.017484806004461961" density="1561.7555055600315" pos="0.0086025245541952854 -0.010753155692744105 -0.012903786831292927" euler="-0.6108652381980153 -0.69813170079773179 0"/>
                      <body name="lower_leg_R" pos="0.015422645345868605 -0.017478998058651083 -0.025704408909781006">
                        <joint name="knee_R" class="knee" axis="-0.5 -1 0"/>
                        <site name="ankle_R" type="cylinder" size="0.00060000000000000006 0.0025999999999999999" pos="-0.03230154033783407 0.0047270546835854734 -0.022059588523398874" zaxis="0 1 0"/>
                        <body name="foot_R" pos="-0.03230154033783407 0.0047270546835854734 -0.022059588523398874">
                          <joint name="ankle_R" class="ankle" axis="0.29999999999999999 1 0"/>
                          <geom name="foot_R_collision" class="collision_primitive_paw" size="0.0032107122078339698 0.012384175658788165" density="2041.159782276932" pos="0.0082744640327606835 -0.0022566720089347322 -0.0022566720089347322" euler="1.570796326794897 1.2217304763960311 0"/>
                          <site name="toe_R" type="cylinder" size="0.00060000000000000006 0.005000000000000001" pos="0.021099943113672619 -0.007614327297542728 -0.0027521664930877329" zaxis="0 1 0"/>
                          <body name="toe_R" pos="0.021099943113672619 -0.007614327297542728 -0.0027521664930877329">
                            <joint name="toe_R" class="toe" axis="0 1 0"/>
                            <geom name="toe_R0_collision" class="collision_primitive_paw" size="0.0023832084241499803 0.0072532430300216808" pos="0.0084966561208825384 0.00084966561208825388 0" euler="1.570796326794897 1.2217304763960311 0"/>
                            <geom name="toe_R1_collision" class="collision_primitive_paw" size="0.0023832084241499803 0.0077713318178803704" pos="0.0080718233148384128 -0.0025489968362647614 0" euler="1.570796326794897 1.2217304763960311 0"/>
                            <geom name="toe_R2_collision" class="collision_primitive_paw" size="0.0023832084241499803 0.0072532430300216808" pos="0.006797324896706031 -0.005522826478573651 0" euler="1.570796326794897 1.2217304763960311 0"/>
                            <site name="sole_R" class="sensor" type="box" size="0.0060000000000000001 0.0040000000000000001 0.002" pos="0.008199999999999999 -0.0024599999999999999 -0.00164" euler="0 0 -0.3490658503988659"/>
                          </body>
                        </body>
                        <geom name="lower_leg_R_collision" class="collision_primitive" size="0.0065568022516732357 0.019233286604908157" density="1302.8668726714393" pos="-0.01202896613332032 -0.00016157869540389129 -0.010574136907576604" quat="0.65643150361110036 0.39014177197659983 0.27795769268188453 0.58277491358567579"/>
                      </body>
                    </body>
                    <body name="vertebra_C1" pos="-0.015789911729839668 0 -0.011881622926183695">
                      <body name="vertebra_C2" pos="-0.0038770537821393178 0 -0.0042264312045172652">
                        <body name="vertebra_C3" pos="-0.0034240268125903012 0 -0.0042630774361130091">
                          <body name="vertebra_C4" pos="-0.0032718746666582431 0 -0.0044168381522190761">
                            <body name="vertebra_C5" pos="-0.0031759742710189944 0 -0.0045693408592138648">
                              <body name="vertebra_C6" pos="-0.0031191938504819988 0 -0.0049013552813431029">
                                <body name="vertebra_C7" pos="-0.0032158112693534266 0 -0.0056443711319981412">
                                  <body name="vertebra_C8" pos="-0.0034458535044797462 0 -0.0055181812721850163">
                                    <body name="vertebra_C9" pos="-0.0042851727751805502 0 -0.0051150182800653058">
                                      <body name="vertebra_C10" pos="-0.0048615451646428186 0 -0.0045621863426624741">
                                        <body name="vertebra_C11" pos="-0.0053747869848973125 0 -0.0043642071689941591">
                                          <body name="vertebra_C12" pos="-0.0061344784606154447 0 -0.0038415028019160788">
                                            <body name="vertebra_C13" pos="-0.0068974274502133105 0 -0.0025924281851720083">
                                              <body name="vertebra_C14" pos="-0.0068250377373438535 0 -0.00090889989329263519">
                                                <body name="vertebra_C15" pos="-0.0065262110691343264 0 -0.00031533099688660593">
                                                  <body name="vertebra_C16" pos="-0.0066939094479125088 0 -0.00013848852705565461">
                                                    <body name="vertebra_C17" pos="-0.0064854262468500281 0 -1.6704671392166639e-05">
                                                      <body name="vertebra_C18" pos="-0.0062074321817976565 0 1.8255731314229671e-10">
                                                        <body name="vertebra_C19" pos="-0.0062042595978254352 0 -8.2019022273763539e-10">
                                                          <body name="vertebra_C20" pos="-0.0062283768199425816 0 2.5165204728144109e-06">
                                                            <body name="vertebra_C21" pos="-0.006117653417468877 0 -0.00010966417183184349">
                                                            <body name="vertebra_C22" pos="-0.0065081078495339024 0 -1.3119874836490384e-05">
                                                            <body name="vertebra_C23" pos="-0.0063907554126239642 0 1.7514014102079473e-09">
                                                            <body name="vertebra_C24" pos="-0.0061807151952515882 0 -1.2471351732920573e-09">
                                                            <body name="vertebra_C25" pos="-0.0059681989517360139 0 1.3794923497782719e-10">
                                                            <body name="vertebra_C26" pos="-0.0056286765801418339 0 -1.3656301989500158e-09">
                                                            <body name="vertebra_C27" pos="-0.0051931202822717831 0 1.3956929420782384e-09">
                                                            <body name="vertebra_C28" pos="-0.005036239104451245 0 5.0739823560597707e-07">
                                                            <body name="vertebra_C29" pos="-0.0047738968371697282 0 -6.2055545704212819e-11">
                                                            <body name="vertebra_C30" pos="-0.0040053516229491288 0 -4.1971831871537384e-07">
                                                            <geom name="vertebra_C30_collision" class="collision_primitive" size="0.00077871372923254967 0.0061625257367268196 0.0034565399400889869" density="1759.1605318714414" pos="-3.4139358007223563e-17 0 0" quat="0 0.70710678118654746 0 0.70710678118654757"/>
                                                            </body>
                                                            <joint name="vertebra_C29_extend" class="caudal_extend" pos="0.002618767786771059 0 3.4041176343692762e-11" axis="-0 1.0000000000000011 0" range="-0.26179938779914941 0.26179938779914941"/>
                                                            <geom name="vertebra_C29_collision" class="collision_primitive" size="0.00077809947542846199 0.0059637751837726682 0.002618767786771059" density="1759.1605318714414" pos="2.2759572004815705e-17 0 0" quat="0 0.70710678118654746 0 0.70710678118654757"/>
                                                            </body>
                                                            <geom name="vertebra_C28_collision" class="collision_primitive" size="0.00077809940557926893 0.0057649202208267516 0.002877779770642519" density="1759.1605318714414" pos="-2.2759572004815705e-17 0 0" quat="0 0.70710678118654746 0 0.70710678118654757"/>
                                                            </body>
                                                            <joint name="vertebra_C27_bend" class="caudal_bend" pos="0.0030614486895500512 0 -8.2278901629262446e-10" axis="-2.6875806186172678e-07 0 -0.99999999999996425" range="-0.26179938779914941 0.26179938779914941"/>
                                                            <geom name="vertebra_C27_collision" class="collision_primitive" size="0.00082776099443435667 0.0055661828373558819 0.0030614486895501609" density="1759.1605318714414" pos="-2.2759572004815705e-17 -5.6898930012039269e-18 0" quat="0 0.70710678118654746 0 0.70710678118654757"/>
                                                            </body>
                                                            <geom name="vertebra_C26_collision" class="collision_primitive" size="0.0008277630200609565 0.0053673316579079264 0.0030614288989454512" density="1759.1605318714414" pos="0 0 0" quat="0 0.70710678118654746 0 0.70710678118654757"/>
                                                            </body>
                                                            <joint name="vertebra_C25_extend" class="caudal_extend" pos="0.0034789224155247198 0 -8.041197849633586e-11" axis="0 1 0" range="-0.26179938779914941 0.26179938779914941"/>
                                                            <geom name="vertebra_C25_collision" class="collision_primitive" size="0.00082776099443435667 0.0051685892685782164 0.0034789224155247211" density="1759.1605318714414" pos="2.2759572004815705e-17 5.6898930012039269e-18 0" quat="0 0.70710678118654746 0 0.70710678118654757"/>
                                                            </body>
                                                            <geom name="vertebra_C24_collision" class="collision_primitive" size="0.00082776120398193593 0.0049697726353770122 0.0034789186902344231" density="1759.1605318714414" pos="0 5.6898930012039269e-18 0" quat="0 0.70710678118654746 0 0.70710678118654757"/>
                                                            </body>
                                                            <joint name="vertebra_C23_bend" class="caudal_bend" pos="0.0037407763302324802 0 -1.0251684686758591e-09" axis="-2.7405232983071981e-07 0 -0.99999999999996292" range="-0.26179938779914941 0.26179938779914941"/>
                                                            <geom name="vertebra_C23_collision" class="collision_primitive" size="0.00082775938790291548 0.0047709754435345531 0.0037407763302326198" density="1759.1605318714414" pos="0 0 0" quat="0 0.70710678118654746 0 0.70710678118654757"/>
                                                            </body>
                                                            <geom name="vertebra_C22_collision" class="collision_primitive" size="0.00082776197232306006 0.0045721781061729416 0.0037407784257084131" density="1759.1605318714414" pos="2.2759572004815705e-17 0 0" quat="0 0.70710678118654746 0 0.70710678118654757"/>
                                                            </body>
                                                            <joint name="vertebra_C21_extend" class="caudal_extend" pos="0.0038531979682482919 0 6.9071870414476718e-05" axis="-0 1 0" range="-0.26179938779914941 0.26179938779914941"/>
                                                            <geom name="vertebra_C21_collision" class="collision_primitive" size="0.00091830915771424766 0.0049721287796273828 0.0038538170047104359" density="1759.1605318714414" pos="-2.2759572004815705e-17 0 0" quat="0 0.70710678118654746 0 0.70710678118654757"/>
                                                            </body>
                                                            <geom name="vertebra_C20_collision" class="collision_primitive" size="0.00089897182770073405 0.0051765363605227321 0.0035961582325398922" density="1759.1605318714414" pos="0 2.8449465006019635e-18 0" quat="0 0.70710678118654746 0 0.70710678118654757"/>
                                                          </body>
                                                          <joint name="vertebra_C19_bend" class="caudal_bend" pos="0.0035962350666522672 0 4.7541480072307734e-10" axis="1.321979214127503e-07 0 -0.99999999999999156" range="-0.26179938779914941 0.26179938779914941"/>
                                                          <geom name="vertebra_C19_collision" class="collision_primitive" size="0.0009803724009543656 0.0051713781431317329 0.003596235066652298" density="1759.1605318714414" pos="0 0 0" quat="0 0.70710678118654746 0 0.70710678118654757"/>
                                                        </body>
                                                        <geom name="vertebra_C18_collision" class="collision_primitive" size="0.00098037365823984142 0.0049127749516628683 0.0035962301772087808" density="1759.1605318714414" pos="-4.5519144009631415e-17 3.5561831257524543e-19 0" quat="0 0.70710678118654746 0 0.70710678118654757"/>
                                                      </body>
                                                      <joint name="vertebra_C17_extend" class="caudal_extend" pos="0.0035962073049271371 0 9.2628393262655162e-06" axis="-0 1 0" range="-0.26179938779914941 0.26179938779914941"/>
                                                      <geom name="vertebra_C17_collision" class="collision_primitive" size="0.00098037337884306899 0.004654210468288511 0.0035962192341685299" density="1759.1605318714414" pos="4.5519144009631415e-17 3.5561831257524543e-19 0" quat="0 0.70710678118654746 0 0.70710678118654757"/>
                                                    </body>
                                                    <geom name="vertebra_C16_collision" class="collision_primitive" size="0.0011268686503171921 0.0043956402514595538 0.0038668927736580372" density="1759.1605318714414" pos="4.5519144009631415e-17 0 0" quat="0 0.70710678118654746 0 0.70710678118654757"/>
                                                  </body>
                                                  <joint name="vertebra_C15_bend" class="caudal_bend" pos="0.0038592752082805002 0 0.00018647099914411401" axis="0.048261319178239691 0 -0.99883474362437763" range="-0.26179938779914941 0.26179938779914941"/>
                                                  <geom name="vertebra_C15_collision" class="collision_primitive" size="0.001107205613516271 0.0041370675899088383 0.003863777499645948" density="1759.1605318714414" pos="0 -2.8449465006019635e-18 0" quat="-3.0484114965156431e-15 0.69918484550468107 3.117107305228081e-15 0.71494094288730958"/>
                                                </body>
                                                <geom name="vertebra_C14_collision" class="collision_primitive" size="0.001107036438770592 0.0038785065407864749 0.003863667836412787" density="1759.1605318714414" pos="-4.5519144009631415e-17 -4.2674197509029454e-18 0" quat="0 0.68661127709289849 0 0.72702472734347823"/>
                                              </body>
                                              <joint name="vertebra_C13_extend" class="caudal_extend" pos="0.004005019444408159 0 0.001505304023099881" axis="-0 1 0" range="-0.26179938779914941 0.26179938779914941"/>
                                              <geom name="vertebra_C13_collision" class="collision_primitive" size="0.0012544237542897461 0.0039599778247065842 0.0042785652913153172" density="1759.1605318714414" pos="-1.1379786002407857e-17 0 1.7780915628762272e-19" quat="1.8921649036461709e-16 0.62939320922622977 -2.3361814295972612e-16 0.7770869888113604"/>
                                            </body>
                                            <geom name="vertebra_C12_collision" class="collision_primitive" size="0.0014601286500692369 0.004146181046962738 0.0042790831066668034" density="1759.1605318714414" pos="0 0 0" quat="1.235560731911126e-17 0.50807932657268906 -7.2884636281232995e-18 0.86131027969567553"/>
                                          </body>
                                          <joint name="vertebra_C11_bend" class="caudal_bend" pos="0.0033221702669597162 0 0.0026975281692883401" axis="0.63034835861330107 0 -0.77631240283375424" range="-0.26179938779914941 0.26179938779914941"/>
                                          <geom name="vertebra_C11_collision" class="collision_primitive" size="0.0014997957274317741 0.0038969448069110508 0.0042794244363903999" density="1759.1605318714414" pos="-2.2759572004815705e-17 0 0" quat="8.0408085539503005e-17 0.43494441859157318 -3.8839207519475621e-17 0.90045730200606311"/>
                                        </body>
                                        <geom name="vertebra_C10_collision" class="collision_primitive" size="0.0020527174696326261 0.0051967769977636644 0.0039378739893436432" density="1759.1605318714414" pos="0 0 -1.4224732503009817e-18" quat="6.6069271991940225e-17 0.40482247803803101 -2.9250288648812828e-17 0.91439529814798803"/>
                                      </body>
                                      <joint name="vertebra_C9_extend" class="caudal_extend" pos="0.0025285567948959962 0 0.003018224679991213" axis="-0 1 0" range="-0.26179938779914941 0.26179938779914941"/>
                                      <geom name="vertebra_C9_collision" class="collision_primitive" size="0.001878352090716362 0.0044948977301828563 0.0039374204352498046" density="1759.1605318714414" pos="0 0 -2.8449465006019635e-18" quat="0.93393633089552841 -2.1886851297021869e-17 0.35743940721945872 5.718710691193161e-17"/>
                                    </body>
                                    <geom name="vertebra_C8_collision" class="collision_primitive" size="0.0018094909843057391 0.003957028646254912 0.0039368746802210808" density="1759.1605318714414" pos="0 0 -2.8449465006019635e-18" quat="0.95575629612546076 -1.8012083974514359e-17 0.29415965463764848 5.8523194440748775e-17"/>
                                  </body>
                                  <joint name="vertebra_C7_bend" class="caudal_bend" pos="0.0018574175338317109 0 0.0032601272369241988" axis="0.86887528707368111 0 -0.49503104499882472" range="-0.26179938779914941 0.26179938779914941"/>
                                  <geom name="vertebra_C7_collision" class="collision_primitive" size="0.001954166125506163 0.0046388986520469189 0.003752123331651092" density="1759.1605318714414" pos="0 0 0" quat="-0.95871816238736907 -0.028643871421635381 -0.2629262253293439 0.10444526687519259"/>
                                </body>
                                <geom name="vertebra_C6_collision" class="collision_primitive" size="0.0023094786331057551 0.0044417925528250626 0.0039176340214908123" density="1759.1605318714414" pos="0 0 -5.6898930012039269e-18" quat="-0.9684724633255426 -0.020165366545190799 -0.2338356379719502 0.083518502060948033"/>
                              </body>
                              <joint name="vertebra_C5_extend" class="caudal_extend" pos="0.0020122482295807328 0 0.0028950637724637299" axis="-0 1 0" range="-0.26179938779914941 0.26179938779914941"/>
                              <geom name="vertebra_C5_collision" class="collision_primitive" size="0.0027271977625787261 0.0037766372552141552 0.0035256966948509221" density="1759.1605318714414" pos="0 0 0" quat="0.95955512298200196 -1.7238177888175469e-17 0.28152080910475341 5.8755805498267679e-17"/>
                            </body>
                            <geom name="vertebra_C4_collision" class="collision_primitive" size="0.0039916958659887312 0.0038516992935910821 0.0042605199851095676" density="1759.1605318714414" pos="0 0 -5.6898930012039269e-18" quat="0.6698964656770412 0.22635972537845331 0.22635972537845331 0.6698964656770412"/>
                          </body>
                          <joint name="vertebra_C3_bend" class="caudal_bend" pos="0.0028146329163340751 0 0.003504352837554861" axis="0.77965718635053138 0 -0.6262065727633116" range="-0.26179938779914941 0.26179938779914941"/>
                          <geom name="vertebra_C3_collision" class="collision_primitive" size="0.0047375869005918496 0.0040974398143589497 0.0044947355054318896" density="1759.1605318714414" pos="0 0 5.6898930012039269e-18" quat="0.658413368499565 0.25786010971272011 0.25786010971272011 0.658413368499565"/>
                        </body>
                        <geom name="vertebra_C2_collision" class="collision_primitive" size="0.0050162198022007942 0.003506151144392788 0.0052641532383859158" density="1759.1605318714414" pos="0 0 0" quat="0.61659450065834553 0.34613757634484821 0.34613757634484821 0.61659450065834553"/>
                      </body>
                      <joint name="vertebra_C1_extend" class="caudal_extend" pos="0.0043423205380006616 0 0.0032675176492370961" axis="0 1 0" range="-0.26179938779914941 0.26179938779914941"/>
                      <geom name="vertebra_C1_collision" class="collision_primitive" size="0.0065789960324764253 0.0023704245686531071 0.0054343738593161106" density="1759.1605318714414" pos="0 -2.7782680669941046e-21 0" quat="0.57724085518430246 0.3506607415056362 0.32402767637757213 0.66244705781984103"/>
                    </body>
                  </body>
                </body>
                <joint name="vertebra_5_bend" class="lumbar_bend" axis="0 0 1"/>
              </body>
              <joint name="vertebra_4_extend" class="lumbar_extend" axis="0 1 0"/>
            </body>
            <joint name="vertebra_3_twist" class="lumbar_twist" axis="1 0 0"/>
          </body>
          <joint name="vertebra_2_bend" class="lumbar_bend" axis="0 0 1"/>
        </body>
        <joint name="vertebra_1_extend" class="lumbar_extend" axis="0 1 0"/>
      </body>
      <body name="vertebra_cervical_5" pos="0.027709064977571626 1.1826143870584833e-05 -0.0010003149103845464">
        <geom name="vertebra_cervical_5_collision" class="nonself_collision_primitive" type="sphere" size="0.0089999999999999993" density="300.0"/>
        <body name="vertebra_cervical_4" pos="0.0024090406000515457 -1.2014969707070054e-05 0.00080957699388570779">
          <geom name="vertebra_cervical_4_collision" class="nonself_collision_primitive" type="sphere" size="0.0083999999999999995" density="300.0"/>
          <body name="vertebra_cervical_3" pos="0.0021502795911542594 1.2081540557691774e-10 0.00094152678442587575">
            <geom name="vertebra_cervical_3_collision" class="nonself_collision_primitive" type="sphere" size="0.0077999999999999988" density="300.0"/>
            <body name="vertebra_cervical_2" pos="0.0018999600588887923 1.2839797205897248e-10 0.00087476208315739933">
              <geom name="vertebra_cervical_2_collision" class="nonself_collision_primitive" type="sphere" size="0.0071999999999999981" density="300.0"/>
              <body name="vertebra_cervical_1" pos="0.0017775116335614109 4.5221276410848836e-10 0.00093507352721358694">
                <geom name="vertebra_cervical_1_collision" class="nonself_collision_primitive" type="sphere" size="0.0065999999999999982" density="300.0"/>
                <body name="vertebra_axis" pos="0.0018823166651467768 -1.7566504879528999e-06 0.001705860606049519">
                  <geom name="vertebra_axis_collision" class="nonself_collision_primitive" type="sphere" size="0.0059999999999999984" density="300.0"/>
                  <body name="vertebra_atlant" pos="0.0024521821591785863 1.7569852384853038e-06 0.0013695547278445642">
                    <geom name="vertebra_atlant_collision" class="nonself_collision_primitive" type="sphere" size="0.0053999999999999994" density="300.0"/>
                    <joint name="vertebra_atlant_extend" class="cervical_extend" pos="2.7405829199983609e-05 -4.9553778337723157e-08 -0.00021152928958272321" axis="0 1 0"/>
                    <body name="skull" pos="0.025955069118141876 4.2023543244686657e-09 0.0017705098757900466">
                      <geom name="skull_0_collision" class="collision_primitive" type="ellipsoid" size="0.022095228007967312 0.016695652173913042 0.01" density="703.1077384096191" pos="-0.0090590434832665979 0 0.00081999999999999998" euler="0 0.17453292519943289 0"/>
                      <geom name="skull_0b_collision" class="collision_primitive" type="ellipsoid" size="0.022095228007967312 0.016695652173913042 0.01" density="1.406215476819238" pos="-0.0090590434832665979 0 0.0032799999999999999" euler="0 0.17453292519943289 0"/>
                      <geom name="skull_F_collision" class="collision_primitive" type="ellipsoid" size="0.0071809491025893778 0.0089043478260869575 0.02" density="703.1077384096191" pos="0.014494469573226558 0 -0.00081999999999999998" euler="0 1.919862177193763 0"/>
                      <geom name="skull_Fb_collision" class="collision_primitive" type="ellipsoid" size="0.0071809491025893778 0.0089043478260869575 0.02" density="1.406215476819238" pos="0.014494469573226558 0 0.00164" euler="0 1.919862177193763 0"/>
                      <geom name="skull_L_collision" class="collision_primitive" type="ellipsoid" size="0.0071809491025893778 0.013356521739130435 0.014" density="703.1077384096191" pos="0.0054354260899599589 0.0045634782608695657 -0.00081999999999999998" euler="0 1.919862177193763 0"/>
                      <geom name="eye_L_collision" class="collision_primitive" type="sphere" group="1" size="0.0040000000000000001 0.0040000000000000001 0.0040000000000000001" rgba="0 0 0 1" pos="0.0011047614003983656 0.012800000000000001 0.0025000000000000001"/>
                      <geom name="skull_R_collision" class="collision_primitive" type="ellipsoid" size="0.0071809491025893778 0.013356521739130435 0.014" density="703.1077384096191" pos="0.0054354260899599589 -0.0045634782608695657 -0.00081999999999999998" euler="0 1.919862177193763 0"/>
                      <geom name="eye_R_collision" class="collision_primitive" type="sphere" group="1" size="0.0040000000000000001 0.0040000000000000001 0.0040000000000000001" rgba="0 0 0 1" pos="0.0011047614003983656 -0.012800000000000001 0.0025000000000000001"/>
                      <geom name="skull_P0_collision" class="collision_primitive" type="box" size="0.0066285684023901946 0.0062330434782608708 0.0016000000000000001" density="703.1077384096191" pos="0.0018118086966533197 0 -0.0057400000000000003"/>
                      <geom name="skull_P1_collision" class="collision_primitive" type="box" size="0.0044190456015934625 0.0040069565217391301 0.0011999999999999999" density="703.1077384096191" pos="0.0063413304382866197 0 -0.0057400000000000003"/>
                      <geom name="skull_P2_collision" class="collision_primitive" type="box" size="0.0011047614003983656 0.0033391304347826088 0.00080000000000000004" density="703.1077384096191" pos="0.0086060913091032705 0 -0.0057400000000000003"/>
                      <geom name="skull_T0_collision" class="collision_primitive" type="ellipsoid" size="0.0055238070019918298 0.0066782608695652177 0.0040000000000000001" density="703.1077384096191" pos="0.029894843494779777 0 -0.0065599999999999999" euler="0 0.52359877559829882 0"/>
                      <geom name="skull_T1_collision" class="collision_primitive" type="ellipsoid" group="1" size="0.0022095228007967312 0.0016695652173913044 0.007000000000000001" rgba="1 1 1 1" density="703.1077384096191" pos="0.028083034798126454 0.00091269565217391301 -0.012299999999999998" euler="0 0.52359877559829882 0"/>
                      <geom name="skull_T2_collision" class="collision_primitive" type="ellipsoid" group="1" size="0.0022095228007967312 0.0016695652173913044 0.007000000000000001" rgba="1 1 1 1" density="703.1077384096191" pos="0.028083034798126454 -0.00091269565217391301 -0.012299999999999998" euler="0 0.52359877559829882 0"/>
                      <joint name="atlas" class="atlas" pos="-0.02843583549004804 0 0"/>
                      <site name="head" class="sensor" type="box" size="0.002 0.002 0.002"/>
                      <camera name="egocentric" fovy="80.0" pos="0.01 0 0.0050000000000000001" euler="0 -1.570796326794897 -1.570796326794897"/>
                      <body name="jaw" pos="0.00045295217416332993 -1.5887977837669331e-08 -0.016399999999999998" euler="0 0.26179938779914941 0">
                        <geom name="jaw_back_collision" class="collision_primitive" type="ellipsoid" size="0.012152375404382021 0.013356521739130435 0.007000000000000001" density="314.05727497690356" pos="-0.010870852179919918 0 0.0020499999999999997" euler="0 0.95993108859688125 0"/>
                        <geom name="jaw_F_collision" class="collision_primitive" type="ellipsoid" size="0.0033142842011950973 0.0066782608695652177 0.012" density="314.05727497690356" pos="0.0027177130449799794 0 -0.0049199999999999999" euler="0 1.8325957145940459 0"/>
                        <geom name="jaw_L_collision" class="collision_primitive" type="ellipsoid" size="0.0099428526035852897 0.0038956521739130444 0.016" density="314.05727497690356" pos="-0.0054354260899599589 0.008214260869565216 0.00081999999999999998" euler="-0.69813170079773179 2.1816615649929121 0.52359877559829882"/>
                        <geom name="jaw_R_collision" class="collision_primitive" type="ellipsoid" size="0.0099428526035852897 0.0038956521739130444 0.016" density="314.05727497690356" pos="-0.0054354260899599589 -0.008214260869565216 0.00081999999999999998" euler="0.69813170079773179 2.1816615649929121 -0.52359877559829882"/>
                        <geom name="jaw_T0_collision" class="collision_primitive" type="ellipsoid" size="0.0033142842011950973 0.0033391304347826088 0.0060000000000000001" density="314.05727497690356" pos="0.012682660876573236 0 -0.0057400000000000003" euler="0 1.2217304763960311 0"/>
                        <geom name="jaw_T1_collision" class="collision_primitive" type="ellipsoid" group="1" size="0.0022095228007967312 0.0013356521739130434 0.007000000000000001" rgba="1 1 1 1" density="314.05727497690356" pos="0.017212182618206534 0.00091269565217391301 -0.0041000000000000003" euler="0 1.134464013796314 0"/>
                        <geom name="jaw_T2_collision" class="collision_primitive" type="ellipsoid" group="1" size="0.0022095228007967312 0.0013356521739130434 0.007000000000000001" rgba="1 1 1 1" density="314.05727497690356" pos="0.017212182618206534 -0.00091269565217391301 -0.0041000000000000003" euler="0 1.134464013796314 0"/>
                        <geom name="jaw_P0_collision" class="collision_primitive" type="box" size="0.0066285684023901946 0.0062330434782608708 0.0016000000000000001" density="314.05727497690356" pos="-0.0027177130449799794 0 0.00081999999999999998" euler="0 0.95993108859688125 0"/>
                        <geom name="jaw_P1_collision" class="collision_primitive" type="box" size="0.0044190456015934625 0.0048973913043478265 0.001" density="314.05727497690356" pos="0 0 -0.00098399999999999985" euler="0 0.52359877559829882 0"/>
                        <geom name="jaw_P2_collision" class="collision_primitive" type="box" size="0.0044190456015934625 0.0040069565217391301 0.001" density="314.05727497690356" pos="0.0027177130449799794 0 -0.0022959999999999999" euler="0 0.43633231299858238 0"/>
                        <geom name="jaw_P3_collision" class="collision_primitive" type="box" size="0.0033142842011950973 0.0028939130434782606 0.00060000000000000006" density="314.05727497690356" pos="0.0047107026112986304 0 -0.0028700000000000006" euler="0 0.26179938779914941 0"/>
                        <joint name="mandible" class="mandible" pos="-0.018499999999999999 0 0.0040000000000000001" axis="0 1 0"/>
                      </body>
                    </body>
                  </body>
                  <joint name="vertebra_axis_twist" class="cervical_twist" pos="9.9439267225693242e-05 7.3323041593157166e-08 -0.00026762400899821309" axis="0.74098459448325726 -0.00069151539353932078 0.6715216694529994"/>
                </body>
                <joint name="vertebra_cervical_1_bend" class="cervical_bend" pos="2.7469839671064701e-05 -2.2175703241969479e-11 -0.0002637692890460073" axis="-0.46556749786463181 0 0.88501237558127699"/>
              </body>
              <joint name="vertebra_cervical_2_extend" class="cervical_extend" pos="1.2951560981522581e-05 -5.7953729860696879e-12 -0.00025387484726577692" axis="0 1 0"/>
            </body>
            <joint name="vertebra_cervical_3_twist" class="cervical_twist" pos="8.1975708702249013e-06 -4.86590177453699e-12 -0.00025442947362712192" axis="0.91603535672916836 5.1468275847153093e-08 0.40109752582391073"/>
          </body>
          <joint name="vertebra_cervical_4_bend" class="cervical_bend" pos="-1.5375952702610769e-05 4.7972607130889212e-07 -0.00027279087898873908" axis="-0.31854757960001961 0 0.94789508360576713"/>
        </body>
        <joint name="vertebra_cervical_5_extend" class="cervical_extend" pos="-0.00019345864674152679 -3.9985802498100721e-07 -0.0002296866127457893" axis="0 1 0"/>
      </body>
      <body name="scapula_L" pos="0.0065599999999999999 0.00164 0.011479999999999999">
        <joint name="scapula_L_supinate" class="scapula_supinate" pos="0 -0.005000000000000001 0" axis="-0 -0 1"/>
        <joint name="scapula_L_abduct" class="scapula_abduct" pos="0 -0.005000000000000001 -0.01" axis="1 -0 -0"/>
        <joint name="scapula_L_extend" class="scapula_extend" pos="0 0 0" axis="0.29999999999999999 1 0"/>
        <site name="shoulder_L" size="0.002" pos="0.0287 0.0098399999999999998 -0.025419999999999998"/>
        <body name="upper_arm_L" pos="0.0287 0.0098399999999999998 -0.025419999999999998">
          <joint name="shoulder_L" class="shoulder" axis="0 1 0"/>
          <joint name="shoulder_sup_L" class="shoulder_sup" axis="0 0 -1"/>
          <site name="elbow_L" type="cylinder" size="0.00060000000000000006 0.0040000000000000001" pos="-0.015931208361332178 0.010355285434865916 -0.022303691705865051" zaxis="0 1 0.20000000000000001"/>
          <body name="lower_arm_L" pos="-0.015931208361332178 0.010355285434865916 -0.022303691705865051">
            <joint name="elbow_L" class="elbow" axis="0 1 0.20000000000000001"/>
            <site name="wrist_L" type="cylinder" size="0.00080000000000000004 0.0033999999999999998" pos="0.021602653764793079 0.012601548029462629 -0.019802432617726989" zaxis="0 1 0"/>
            <body name="hand_L" pos="0.021602653764793079 0.012601548029462629 -0.019802432617726989">
              <joint name="wrist_L" class="wrist" axis="0.59999999999999998 -1 0"/>
              <geom name="hand_L_collision" class="collision_primitive_paw" type="ellipsoid" size="0.0064701915886817927 0.0036972523363895953 0.0022183514018337567" density="2531.7812283135054" pos="0.0015158734579197339 0.00075793672895986693 -0.004547620373759202" euler="-0.69813170079773179 0.87266462599716477 0.78539816339744828"/>
              <site name="finger_L" type="cylinder" size="0.00060000000000000006 0.005000000000000001" pos="0.0030317469158394677 0.0015158734579197339 -0.0083373040185585352" zaxis="-0.20000000000000001 1 0"/>
              <body name="finger_L" pos="0.0030317469158394677 0.0015158734579197339 -0.0083373040185585352">
                <joint name="finger_L" class="finger" axis="-0.5 1 0"/>
                <geom name="finger_L0_collision" class="collision_primitive_paw" size="0.0018486261681947976 0.0032350957943408963" pos="0.0049265887382391356 -0.00075793672895986693 0" euler="1.570796326794897 -1.308996938995747 0"/>
                <geom name="finger_L1_collision" class="collision_primitive_paw" size="0.0018486261681947976 0.0036972523363895953" pos="0.004547620373759202 0.0018948418223996672 0" euler="1.570796326794897 -1.099557428756428 0"/>
                <geom name="finger_L2_collision" class="collision_primitive_paw" size="0.0018486261681947976 0.0032350957943408963" pos="0.002652778551359535 0.0037896836447993353 0" euler="1.570796326794897 -0.95993108859688125 0"/>
                <site name="palm_L" class="sensor" type="box" size="0.0040000000000000001 0.0040000000000000001 0.002" pos="0.0049199999999999999 0.0024599999999999999 -0.00164" euler="0 0 0.48869219055841229"/>
              </body>
            </body>
            <geom name="radius_L_collision" class="collision_primitive" size="0.0037321657926979914 0.015916589410035552" pos="0.011505454675267295 0.0068507326671297646 -0.012226324913508857" quat="0.023764932308462921 0.79177214415182184 0.42322934679317159 0.43978292344135678"/>
            <geom name="ulna_L_collision" class="collision_primitive" size="0.0043907832855270487 0.013172349856581148" pos="0.0067497643635477597 0.0049924186526332653 -0.0094898484523118203" quat="0.012822444520418631 0.74462498727826065 0.47760656071953278 0.46611284727523911"/>
          </body>
          <geom name="humerus_L_collision" class="collision_primitive" size="0.0077713211518693568 0.015542642303738714" pos="-0.007743344450064288 0.0057879788900726658 -0.011983352737222017" quat="0.47256099918016298 0.34500828054201771 0.00070160501549135191 0.8109592444517103"/>
        </body>
        <geom name="scapula_L_collision" class="nonself_collision_primitive" type="ellipsoid" size="0.0050053708255290994 0.014631827920675281 0.024311044067144391" density="513.5646123028544" pos="0.01757062251063465 0.0086369166801125909 -0.015229522492676917" quat="0.18441940626963749 0.76922228553766514 0.47403228455170038 0.38675567381237091"/>
      </body>
      <body name="scapula_R" pos="0.0065599999999999999 -0.00164 0.011479999999999999">
        <joint name="scapula_R_supinate" class="scapula_supinate" pos="0 0.005000000000000001 0" axis="0 0 -1"/>
        <joint name="scapula_R_abduct" class="scapula_abduct" pos="0 0.005000000000000001 -0.01" axis="-1 0 0"/>
        <joint name="scapula_R_extend" class="scapula_extend" pos="0 0 0" axis="-0.29999999999999999 1 0"/>
        <site name="shoulder_R" size="0.002" pos="0.0287 -0.0098399999999999998 -0.025419999999999998"/>
        <body name="upper_arm_R" pos="0.0287 -0.0098399999999999998 -0.025419999999999998">
          <joint name="shoulder_R" class="shoulder" axis="0 1 0"/>
          <joint name="shoulder_sup_R" class="shoulder_sup" axis="-0 -0 1"/>
          <site name="elbow_R" type="cylinder" size="0.00060000000000000006 0.0040000000000000001" pos="-0.015931208361332178 -0.010355285434865916 -0.022303691705865051" zaxis="0 1 -0.20000000000000001"/>
          <body name="lower_arm_R" pos="-0.015931208361332178 -0.010355285434865916 -0.022303691705865051">
            <joint name="elbow_R" class="elbow" axis="0 1 -0.20000000000000001"/>
            <site name="wrist_R" type="cylinder" size="0.00080000000000000004 0.0033999999999999998" pos="0.021602653764793079 -0.012601548029462629 -0.019802432617726989" zaxis="0 1 0"/>
            <body name="hand_R" pos="0.021602653764793079 -0.012601548029462629 -0.019802432617726989">
              <joint name="wrist_R" class="wrist" axis="-0.59999999999999998 -1 0"/>
              <geom name="hand_R_collision" class="collision_primitive_paw" type="ellipsoid" size="0.0064701915886817927 0.0036972523363895953 0.0022183514018337567" density="2531.7812283135054" pos="0.0015158734579197339 -0.00075793672895986693 -0.004547620373759202" euler="0.69813170079773179 0.87266462599716477 -0.78539816339744828"/>
              <site name="finger_R" type="cylinder" size="0.00060000000000000006 0.005000000000000001" pos="0.0030317469158394677 -0.0015158734579197339 -0.0083373040185585352" zaxis="0.20000000000000001 1 0"/>
              <body name="finger_R" pos="0.0030317469158394677 -0.0015158734579197339 -0.0083373040185585352">
                <joint name="finger_R" class="finger" axis="0.5 1 0"/>
                <geom name="finger_R0_collision" class="collision_primitive_paw" size="0.0018486261681947976 0.0032350957943408963" pos="0.0049265887382391356 0.00075793672895986693 0" euler="1.570796326794897 1.308996938995747 0"/>
                <geom name="finger_R1_collision" class="collision_primitive_paw" size="0.0018486261681947976 0.0036972523363895953" pos="0.004547620373759202 -0.0018948418223996672 0" euler="1.570796326794897 1.099557428756428 0"/>
                <geom name="finger_R2_collision" class="collision_primitive_paw" size="0.0018486261681947976 0.0032350957943408963" pos="0.002652778551359535 -0.0037896836447993353 0" euler="1.570796326794897 0.95993108859688125 0"/>
                <site name="palm_R" class="sensor" type="box" size="0.0040000000000000001 0.0040000000000000001 0.002" pos="0.0049199999999999999 -0.0024599999999999999 -0.00164" euler="0 0 -0.48869219055841229"/>
              </body>
            </body>
            <geom name="radius_R_collision" class="collision_primitive" size="0.0037321657926979914 0.015916589410035552" pos="0.011505461395781584 -0.0068511746740596022 -0.012226329953604027" quat="0.43978285859011762 0.42323047325609903 0.79177155870747651 0.023765576358593481"/>
            <geom name="ulna_R_collision" class="collision_primitive" size="0.0043907832855270487 0.013172349856581148" pos="0.0067497669307536893 -0.0049928587360002054 -0.0094898485071555749" quat="0.46611278282571561 0.47760677953250608 0.74462488546938377 0.01282254930824632"/>
          </body>
          <geom name="humerus_R_collision" class="collision_primitive" size="0.0077713211518693568 0.015542642303738714" pos="-0.0077433418895144464 -0.0057883475605501741 -0.011983350671240126" quat="0.81095939353104862 0.00070139480829139946 0.34500827950404478 0.47256074441571583"/>
        </body>
        <geom name="scapula_R_collision" class="nonself_collision_primitive" type="ellipsoid" size="0.0050053702667355532 0.014631831273436551 0.024311039596796039" density="513.5646463925378" pos="0.017570620188504527 -0.0086372952673672201 -0.015229520628109939" quat="0.38675569721296882 0.47403213120406879 0.76922234964236824 0.1844194839763772"/>
      </body>
    </body>
  </worldbody>
  <contact>
    <exclude name="pelvis:vertebra_C3" body1="pelvis" body2="vertebra_C3"/>
    <exclude name="pelvis:vertebra_C4" body1="pelvis" body2="vertebra_C4"/>
    <exclude name="vertebra_axis:skull" body1="vertebra_axis" body2="skull"/>
  </contact>
  <tendon>
    <fixed name="lumbar_extend" class="lumbar_extend">
      <joint joint="vertebra_1_extend" coef="0.611232384148"/>
      <joint joint="vertebra_4_extend" coef="0.388767615852"/>
    </fixed>
    <fixed name="lumbar_bend" class="lumbar_bend">
      <joint joint="vertebra_2_bend" coef="0.673440169021"/>
      <joint joint="vertebra_5_bend" coef="0.326559830979"/>
    </fixed>
    <fixed name="lumbar_twist" class="lumbar_twist">
      <joint joint="vertebra_3_twist" coef="0.567275016346"/>
      <joint joint="vertebra_6_twist" coef="0.432724983654"/>
    </fixed>
    <fixed name="cervical_extend" class="cervical_extend">
      <joint joint="vertebra_cervical_5_extend" coef="0.341713547174"/>
      <joint joint="vertebra_cervical_2_extend" coef="0.332408292936"/>
      <joint joint="vertebra_atlant_extend" coef="0.32587815989"/>
    </fixed>
    <fixed name="cervical_bend" class="cervical_bend">
      <joint joint="vertebra_cervical_4_bend" coef="0.50743949691"/>
      <joint joint="vertebra_cervical_1_bend" coef="0.49256050309"/>
    </fixed>
    <fixed name="cervical_twist" class="cervical_twist">
      <joint joint="vertebra_cervical_3_twist" coef="0.496142185731"/>
      <joint joint="vertebra_axis_twist" coef="0.503857814269"/>
    </fixed>
    <fixed name="caudal_extend" class="caudal_extend">
      <joint joint="vertebra_C1_extend" coef="0.427378558354"/>
      <joint joint="vertebra_C5_extend" coef="0.255659487498"/>
      <joint joint="vertebra_C9_extend" coef="0.162015531448"/>
      <joint joint="vertebra_C13_extend" coef="0.0908820320559"/>
      <joint joint="vertebra_C17_extend" coef="0.0419255178006"/>
      <joint joint="vertebra_C21_extend" coef="0.0165806599147"/>
      <joint joint="vertebra_C25_extend" coef="0.00419149795848"/>
      <joint joint="vertebra_C29_extend" coef="0.00136671497022"/>
    </fixed>
    <fixed name="caudal_bend" class="caudal_bend">
      <joint joint="vertebra_C3_bend" coef="0.465959582647"/>
      <joint joint="vertebra_C7_bend" coef="0.208208889814"/>
      <joint joint="vertebra_C11_bend" coef="0.156709309744"/>
      <joint joint="vertebra_C15_bend" coef="0.105497877966"/>
      <joint joint="vertebra_C19_bend" coef="0.0454826232883"/>
      <joint joint="vertebra_C23_bend" coef="0.0146832624497"/>
      <joint joint="vertebra_C27_bend" coef="0.00345845409169"/>
    </fixed>
  </tendon>
  <actuator>
    <general name="lumbar_extend" forcerange="-20 20" tendon="lumbar_extend" dyntype="filter" biastype="affine" dynprm="0.040000000000000001" gainprm="7.8539816339744828" biasprm="-2.617993877991494 -20"/>
    <general name="lumbar_bend" forcerange="-20 20" tendon="lumbar_bend" dyntype="filter" biastype="affine" dynprm="0.040000000000000001" gainprm="10.471975511965979" biasprm="0 -20"/>
    <general name="lumbar_twist" forcerange="-20 20" tendon="lumbar_twist" dyntype="filter" biastype="affine" dynprm="0.040000000000000001" gainprm="10.471975511965979" biasprm="0 -20"/>
    <general name="cervical_extend" forcerange="-20 20" tendon="cervical_extend" dyntype="filter" biastype="affine" dynprm="0.040000000000000001" gainprm="10.181087303300259" biasprm="2.0362174606600512 -20"/>
    <general name="cervical_bend" forcerange="-20 20" tendon="cervical_bend" dyntype="filter" biastype="affine" dynprm="0.040000000000000001" gainprm="12.217304763960311" biasprm="0 -20"/>
    <general name="cervical_twist" forcerange="-20 20" tendon="cervical_twist" dyntype="filter" biastype="affine" dynprm="0.040000000000000001" gainprm="12.217304763960311" biasprm="0 -20"/>
    <general name="caudal_extend" forcerange="-0.10000000000000001 0.10000000000000001" tendon="caudal_extend" dyntype="filter" biastype="affine" dynprm="0.040000000000000001" gainprm="0.026179938779914948" biasprm="0 -0.10000000000000001"/>
    <general name="caudal_bend" forcerange="-0.10000000000000001 0.10000000000000001" tendon="caudal_bend" dyntype="filter" biastype="affine" dynprm="0.040000000000000001" gainprm="0.026179938779914941" biasprm="0 -0.10000000000000001"/>
    <general name="hip_L_supinate" forcerange="-0.14999999999999999 0.14999999999999999" joint="hip_L_supinate" dyntype="filter" biastype="affine" dynprm="0.040000000000000001" gainprm="0.1570796326794896" biasprm="0 -0.29999999999999999"/>
    <general name="hip_L_abduct" forcerange="-0.14999999999999999 0.14999999999999999" joint="hip_L_abduct" dyntype="filter" biastype="affine" dynprm="0.040000000000000001" gainprm="0.2094395102393195" biasprm="0.10471975511965979 -0.29999999999999999"/>
    <general name="hip_L_extend" forcerange="-0.14999999999999999 0.14999999999999999" joint="hip_L_extend" dyntype="filter" biastype="affine" dynprm="0.040000000000000001" gainprm="0.39269908169872408" biasprm="-0.078539816339744842 -0.29999999999999999"/>
    <general name="knee_L" forcerange="-0.074999999999999997 0.074999999999999997" joint="knee_L" dyntype="filter" biastype="affine" dynprm="0.040000000000000001" gainprm="0.20682151636132801" biasprm="0.02356194490192345 -0.14999999999999999"/>
    <general name="ankle_L" forcerange="-0.050000000000000003 0.050000000000000003" joint="ankle_L" dyntype="filter" biastype="affine" dynprm="0.040000000000000001" gainprm="0.076794487087750496" biasprm="0.062831853071795868 -0.10000000000000001"/>
    <general name="toe_L" forcerange="-0.0025000000000000001 0.0025000000000000001" joint="toe_L" dyntype="filter" biastype="affine" dynprm="0.040000000000000001" gainprm="0.0021816615649929119" biasprm="0.0021816615649929119 -0.0050000000000000001"/>
    <general name="hip_R_supinate" forcerange="-0.14999999999999999 0.14999999999999999" joint="hip_R_supinate" dyntype="filter" biastype="affine" dynprm="0.040000000000000001" gainprm="0.1570796326794896" biasprm="0 -0.29999999999999999"/>
    <general name="hip_R_abduct" forcerange="-0.14999999999999999 0.14999999999999999" joint="hip_R_abduct" dyntype="filter" biastype="affine" dynprm="0.040000000000000001" gainprm="0.2094395102393195" biasprm="0.10471975511965979 -0.29999999999999999"/>
    <general name="hip_R_extend" forcerange="-0.14999999999999999 0.14999999999999999" joint="hip_R_extend" dyntype="filter" biastype="affine" dynprm="0.040000000000000001" gainprm="0.39269908169872408" biasprm="-0.078539816339744842 -0.29999999999999999"/>
    <general name="knee_R" forcerange="-0.074999999999999997 0.074999999999999997" joint="knee_R" dyntype="filter" biastype="affine" dynprm="0.040000000000000001" gainprm="0.20682151636132801" biasprm="0.02356194490192345 -0.14999999999999999"/>
    <general name="ankle_R" forcerange="-0.050000000000000003 0.050000000000000003" joint="ankle_R" dyntype="filter" biastype="affine" dynprm="0.040000000000000001" gainprm="0.076794487087750496" biasprm="0.062831853071795868 -0.10000000000000001"/>
    <general name="toe_R" forcerange="-0.0025000000000000001 0.0025000000000000001" joint="toe_R" dyntype="filter" biastype="affine" dynprm="0.040000000000000001" gainprm="0.0021816615649929119" biasprm="0.0021816615649929119 -0.0050000000000000001"/>
    <general name="atlas" forcerange="-0.025000000000000001 0.025000000000000001" joint="atlas" dyntype="filter" biastype="affine" dynprm="0.040000000000000001" gainprm="0.021816615649929118" biasprm="0.017453292519943299 -0.050000000000000003"/>
    <general name="mandible" forcerange="-0.025000000000000001 0.025000000000000001" joint="mandible" dyntype="filter" biastype="affine" dynprm="0.040000000000000001" gainprm="0.01396263401595464" biasprm="-0.00087266462599716599 -0.050000000000000003"/>
    <general name="scapula_L_supinate" forcerange="-0.25 0.25" joint="scapula_L_supinate" dyntype="filter" biastype="affine" dynprm="0.040000000000000001" gainprm="0.04799655442984406" biasprm="0.039269908169872407 -0.5"/>
    <general name="scapula_L_abduct" forcerange="-0.25 0.25" joint="scapula_L_abduct" dyntype="filter" biastype="affine" dynprm="0.040000000000000001" gainprm="0.1308996938995747" biasprm="0 -0.5"/>
    <general name="scapula_L_extend" forcerange="-0.25 0.25" joint="scapula_L_extend" dyntype="filter" biastype="affine" dynprm="0.040000000000000001" gainprm="0.017453292519943299" biasprm="0 -0.5"/>
    <general name="shoulder_L" forcerange="-0.14999999999999999 0.14999999999999999" joint="shoulder_L" dyntype="filter" biastype="affine" dynprm="0.040000000000000001" gainprm="0.3272492347489368" biasprm="-0.065449846949787366 -0.29999999999999999"/>
    <general name="shoulder_sup_L" forcerange="-0.14999999999999999 0.14999999999999999" joint="shoulder_sup_L" dyntype="filter" biastype="affine" dynprm="0.040000000000000001" gainprm="0.12566370614359171" biasprm="0.1099557428756428 -0.29999999999999999"/>
    <general name="elbow_L" forcerange="-0.14999999999999999 0.14999999999999999" joint="elbow_L" dyntype="filter" biastype="affine" dynprm="0.040000000000000001" gainprm="0.2748893571891069" biasprm="-0.1178097245096173 -0.29999999999999999"/>
    <general name="wrist_L" forcerange="-0.050000000000000003 0.050000000000000003" joint="wrist_L" dyntype="filter" biastype="affine" dynprm="0.040000000000000001" gainprm="0.1221730476396031" biasprm="0.087266462599716474 -0.10000000000000001"/>
    <general name="finger_L" forcerange="-0.025000000000000001 0.025000000000000001" joint="finger_L" dyntype="filter" biastype="affine" dynprm="0.040000000000000001" gainprm="0.039269908169872407" biasprm="0.039269908169872407 -0.050000000000000003"/>
    <general name="scapula_R_supinate" forcerange="-0.25 0.25" joint="scapula_R_supinate" dyntype="filter" biastype="affine" dynprm="0.040000000000000001" gainprm="0.04799655442984406" biasprm="0.039269908169872407 -0.5"/>
    <general name="scapula_R_abduct" forcerange="-0.25 0.25" joint="scapula_R_abduct" dyntype="filter" biastype="affine" dynprm="0.040000000000000001" gainprm="0.1308996938995747" biasprm="0 -0.5"/>
    <general name="scapula_R_extend" forcerange="-0.25 0.25" joint="scapula_R_extend" dyntype="filter" biastype="affine" dynprm="0.040000000000000001" gainprm="0.017453292519943299" biasprm="0 -0.5"/>
    <general name="shoulder_R" forcerange="-0.14999999999999999 0.14999999999999999" joint="shoulder_R" dyntype="filter" biastype="affine" dynprm="0.040000000000000001" gainprm="0.3272492347489368" biasprm="-0.065449846949787366 -0.29999999999999999"/>
    <general name="shoulder_sup_R" forcerange="-0.14999999999999999 0.14999999999999999" joint="shoulder_sup_R" dyntype="filter" biastype="affine" dynprm="0.040000000000000001" gainprm="0.12566370614359171" biasprm="0.1099557428756428 -0.29999999999999999"/>
    <general name="elbow_R" forcerange="-0.14999999999999999 0.14999999999999999" joint="elbow_R" dyntype="filter" biastype="affine" dynprm="0.040000000000000001" gainprm="0.2748893571891069" biasprm="-0.1178097245096173 -0.29999999999999999"/>
    <general name="wrist_R" forcerange="-0.050000000000000003 0.050000000000000003" joint="wrist_R" dyntype="filter" biastype="affine" dynprm="0.040000000000000001" gainprm="0.1221730476396031" biasprm="0.087266462599716474 -0.10000000000000001"/>
    <general name="finger_R" forcerange="-0.025000000000000001 0.025000000000000001" joint="finger_R" dyntype="filter" biastype="affine" dynprm="0.040000000000000001" gainprm="0.039269908169872407" biasprm="0.039269908169872407 -0.050000000000000003"/>
  </actuator>
  <sensor>
    <accelerometer name="accelerometer" site="head"/>
    <velocimeter name="velocimeter" site="head"/>
    <gyro name="gyro" site="head"/>
    <touch name="palm_L" site="palm_L"/>
    <touch name="palm_R" site="palm_R"/>
    <touch name="sole_L" site="sole_L"/>
    <touch name="sole_R" site="sole_R"/>
    <subtreelinvel name="torso" body="torso"/>
  </sensor>
  <compiler angle="radian" meshdir="./"/>
</mujoco>

