<mujoco model="rat">
  <option timestep="0.002"/>
  <visual>
    <quality shadowsize="2048"/>
    <headlight ambient="0.4 0.4 0.4" diffuse="0.8 0.8 0.8" specular="0.1 0.1 0.1"/>
    <!-- <map znear="0.0002"/> -->
  </visual>
  <default>
    <mesh scale="1 1 1"/>
    <joint limited="true" solreflimit="0.01 1" solimplimit="0.99 0.9999 0" armature="6e-08" damping="0.0001"/>
    <geom friction="0.7 0.005 0.0001" solref="0.005 1"/>
    <site group="3" rgba="0 0 1 1"/>
    <general ctrllimited="true" ctrlrange="-1 1" gainprm="0.01"/>
    <default class="bone">
      <geom contype="0" conaffinity="0" group="0" rgba="0.5 0.5 0.5 1" density="1100.0"/>
    </default>
    <default class="collision">
      <geom contype="1" conaffinity="1" condim="1" group="2"/>
      <default class="collision_primitive">
        <!-- Set the group 2 and collusion_primitive_paw A term to 1 to view. -->
        <geom type="capsule" group="2" rgba="0 0.5 0.5 1" density="500.0"/>
        <default class="collision_primitive_paw">
          <geom condim="3" priority="1" rgba="0 0.6 0.7 1" friction="1.5 0.005 0.0001"/>
        </default>
        <default class="nonself_collision_primitive">
          <geom conaffinity="0"/>
        </default>
      </default>
    </default>
    <default class="lumbar">
      <joint group="3" pos="0.003 0 -0.003" armature="1e-05" damping="0.03"/>
      <general gainprm="0.15"/>
      <default class="lumbar_extend">
        <joint stiffness="0.02" range="-30 15"/>
        <tendon range="-1 1"/>
        <general gainprm="0.4"/>
      </default>
      <default class="lumbar_bend">
        <joint stiffness="0.03" range="-30 30"/>
        <tendon range="-1 1"/>
      </default>
      <default class="lumbar_twist">
        <joint stiffness="0.03" range="-30 30"/>
        <tendon range="-1 1"/>
      </default>
    </default>
    <default class="cervical">
      <joint group="3" pos="-0.02 0 -0.05" stiffness="1.0" armature="0.001" damping="5.0"/>
      <default class="cervical_extend">
        <joint range="-23.33333333333334 35"/>
        <tendon range="-1 1"/>
        <general gainprm="0.5"/>
      </default>
      <default class="cervical_bend">
        <joint range="-35 35"/>
        <tendon range="-1 1"/>
        <general gainprm="0.5"/>
      </default>
      <default class="cervical_twist">
        <joint range="-35 35"/>
        <tendon range="-1 1"/>
        <general gainprm="0.5"/>
      </default>
    </default>
    <default class="atlas">
      <joint axis="0 -1 0" stiffness="0.002" range="-5 45" damping="0.002"/>
      <general gainprm="0.025"/>
    </default>
    <default class="mandible">
      <joint stiffness="0.002" range="-17 15" springref="-18.0" damping="0.002"/>
      <general gainprm="0.025"/>
    </default>
    <default class="caudal">
      <joint group="3" stiffness="1e-05" damping="0.01"/>
      <general gainprm="0.005"/>
      <default class="caudal_extend">
        <joint range="-7.5 7.5"/>
        <tendon range="-0.05 0.05"/>
      </default>
      <default class="caudal_bend">
        <joint range="-8.571428571428571 8.571428571428571"/>
        <tendon range="-0.2 0.2"/>
      </default>
    </default>
    <default class="hip">
      <joint armature="1e-05" damping="0.02"/>
      <general gainprm="0.15"/>
      <default class="hip_supinate">
        <joint range="-30 30"/>
      </default>
      <default class="hip_abduct">
        <joint range="-20 60"/>
      </default>
      <default class="hip_extend">
        <joint range="-90 60"/>
        <general gainprm="0.15"/>
      </default>
    </default>
    <default class="knee">
      <joint range="-70 88" damping="0.005"/>
      <general gainprm="0.075"/>
    </default>
    <default class="ankle">
      <joint range="-8 80" damping="0.003"/>
      <general gainprm="0.05"/>
    </default>
    <default class="toe">
      <joint range="0 50" damping="0.0001"/>
      <general gainprm="0.0025"/>
    </default>
    <default class="scapula">
      <joint damping="0.005"/>
      <general gainprm="0.25"/>
      <default class="scapula_supinate">
        <joint pos="0 0.005000000000000001 0" range="-1 10"/>
      </default>
      <default class="scapula_abduct">
        <joint pos="0 0.005000000000000001 -0.01" range="-15 15"/>
      </default>
      <default class="scapula_extend">
        <joint pos="0 0 0" range="-2 2"/>
        <general gainprm="0.25"/>
      </default>
    </default>
    <default class="shoulder">
      <joint range="-75 50" damping="0.005"/>
      <general gainprm="0.15"/>
    </default>
    <default class="shoulder_sup">
      <joint range="-3 45" damping="0.005"/>
      <general gainprm="0.15"/>
    </default>
    <default class="elbow">
      <joint range="-75 30" damping="0.003"/>
      <general gainprm="0.15"/>
    </default>
    <default class="wrist">
      <joint range="-20 120" damping="0.002"/>
      <general gainprm="0.05"/>
    </default>
    <default class="finger">
      <joint range="0 90" damping="0.002"/>
      <general gainprm="0.025"/>
    </default>
    <default class="sensor">
      <site group="4"/>
    </default>
  </default>
  <statistic meansize="0.003"/>
  <asset>
    <texture name="skybox" type="skybox" builtin="gradient" rgb1="0.4 0.6 0.8" rgb2="0 0 0" mark="random" markrgb="1 1 1" width="800" height="800"/>
    <texture name="grid" type="2d" builtin="checker" rgb1="0.1 0.2 0.3" rgb2="0.2 0.3 0.4" mark="edge" markrgb="0.2 0.3 0.4" width="300" height="300"/>
    <material name="grid" texture="grid" texrepeat="1 1" texuniform="true" reflectance="0.2"/>
    <material name="self" rgba="0.7 0.5 0.3 1"/>
    <material name="self_default" rgba="0.7 0.5 0.3 1"/>
    <material name="self_highlight" rgba="0 0.5 0.3 1"/>
    <material name="effector" rgba="0.7 0.4 0.2 1"/>
    <material name="effector_default" rgba="0.7 0.4 0.2 1"/>
    <material name="effector_highlight" rgba="0 0.5 0.3 1"/>
    <material name="decoration" rgba="0.3 0.5 0.7 1"/>
    <material name="eye" rgba="0 0.2 1 1"/>
    <material name="target" rgba="0.6 0.3 0.3 1"/>
    <material name="target_default" rgba="0.6 0.3 0.3 1"/>
    <material name="target_highlight" rgba="0.6 0.3 0.3 0.4"/>
    <skin name="skin" file="rat_skin_walker.skn"/>
    <!-- <hfield name="terrain" nrow="201" ncol="201" size="6 6 0.5 0.1"/> -->
  </asset>
  <worldbody>
    <!-- <geom name="floor" type="plane" size="20 20 0.1" material="grid"/> -->
    <body name="torso" pos="0.03779909822656449 2.510396265428607e-07 0.079377527599024">
      <!-- <freejoint name="root"/> -->
      <site name="root" size=".01" rgba="0.5 0.5 0.5 0"/>
      <light name="light" mode="trackcom" pos="0 0 3"/>
      <camera name="back" mode="trackcom" pos="-1 0 0.5" xyaxes="0 -1 0 1 0 2"/>
      <camera name="side" mode="trackcom" pos="0 -.75 0.5" xyaxes="1 0 0 0 1.25 2"/>
      <geom name="collision_torso" class="nonself_collision_primitive" type="ellipsoid" size="0.05 0.024 0.026" density="600.0" pos="-0.01 0 0" euler="0 10 0"/>
      <body name="vertebra_1" pos="-0.02338956544708357 -2.293092186291426e-07 0.02054445964206206">
        <geom name="vertebra_1_collision" class="nonself_collision_primitive" type="sphere" size="0.01" pos="0 0 -0.002"/>
        <body name="vertebra_2" pos="-0.006865507725997216 3.164394620315175e-06 0.0006488930120467362">
          <geom name="vertebra_2_collision" class="nonself_collision_primitive" type="sphere" size="0.01" pos="0 0 -0.002"/>
          <body name="vertebra_3" pos="-0.007947764234807817 -1.269588860196056e-05 -0.0001154538889612255">
            <geom name="vertebra_3_collision" class="nonself_collision_primitive" type="sphere" size="0.01" pos="0 0 -0.002"/>
            <body name="vertebra_4" pos="-0.008265492908764677 1.0665976984345e-05 -0.001584530210795701">
              <geom name="vertebra_4_collision" class="nonself_collision_primitive" type="sphere" size="0.01" pos="0 0 -0.002"/>
              <body name="vertebra_5" pos="-0.008402520197930613 -7.566260548442953e-06 -0.003046420705832262">
                <geom name="vertebra_5_collision" class="nonself_collision_primitive" type="sphere" size="0.01" pos="0 0 -0.002"/>
                <body name="vertebra_6" pos="-0.007543029798392088 6.40785625482323e-06 -0.004440393235399798">
                  <geom name="vertebra_6_collision" class="nonself_collision_primitive" type="sphere" size="0.01" pos="0 0 -0.002"/>
                  <joint name="vertebra_6_twist" class="lumbar_twist" axis="1 0 0"/>
                  <body name="pelvis" pos="-0.01594074292541946 4.284416382708426e-06 -0.009903637597283577">
                    <geom name="collision_pelvis_L" class="nonself_collision_primitive" size="0.013 0.021 0" pos="-0.001 0.008 -0.007000000000000001" euler="0 50 0"/>
                    <geom name="collision_pelvis_R" class="nonself_collision_primitive" size="0.013 0.021 0" pos="-0.001 -0.008 -0.007000000000000001" euler="0 50 0"/>
                    <geom name="collision_pelvis_gut" class="nonself_collision_primitive" type="ellipsoid" size="0.02 0.02 0.018" pos="0.025 0 -0.02" euler="0 -30 0"/>
                    <site name="hip_L" size="0.0022" pos="-0.005866210264347091 0.01401372452038472 -0.01205832109893569"/>
                    <site name="hip_R" size="0.0022" pos="-0.005866210264347091 -0.01401372452038472 -0.01205832109893569"/>
                    <body name="upper_leg_L" pos="-0.005866210264347091 0.01401372452038472 -0.01205832109893569">
                      <joint name="hip_L_supinate" class="hip_supinate" axis="-0 -0 1"/>
                      <joint name="hip_L_abduct" class="hip_abduct" axis="1 -0 -0"/>
                      <joint name="hip_L_extend" class="hip_extend" axis="0 1 0"/>
                      <site name="knee_L" type="cylinder" size="0.0006000000000000001 0.004" pos="0.02151365485613957 0.02438214217029151 -0.03585609142689928" zaxis="0 1 0"/>
                      <geom name="upper_leg_L0_collision" class="collision_primitive" size="0.01 0.02" pos="0.012 0.015 -0.018" euler="35 -40 0"/>
                      <body name="lower_leg_L" pos="0.02151365485613957 0.02438214217029151 -0.03585609142689928">
                        <joint name="knee_L" class="knee" axis="0.5 -1 0"/>
                        <site name="ankle_L" type="cylinder" size="0.0006000000000000001 0.0026" pos="-0.04294138476031627 -0.006284105086875552 -0.02932582373875257" zaxis="0 1 0"/>
                        <body name="foot_L" pos="-0.04294138476031627 -0.006284105086875552 -0.02932582373875257">
                          <joint name="ankle_L" class="ankle" axis="-0.3 1 0"/>
                          <geom name="foot_L_collision" class="collision_primitive_paw" size="0.003500000000000001 0.0135" pos="0.011 0.003 -0.003" euler="90 -70 0"/>
                          <site name="toe_L" type="cylinder" size="0.0006000000000000001 0.005000000000000001" pos="0.02483323181906177 0.008961557569487508 -0.003239117193790665" zaxis="0 1 0"/>
                          <body name="toe_L" pos="0.02483323181906177 0.008961557569487508 -0.003239117193790665">
                            <joint name="toe_L" class="toe" axis="0 1 0"/>
                            <geom name="toe_L0_collision" class="collision_primitive_paw" size="0.0023 0.007000000000000001" pos="0.01 -0.001 0" euler="90 -70 0"/>
                            <geom name="toe_L1_collision" class="collision_primitive_paw" size="0.0023 0.0075" pos="0.009500000000000001 0.003 0" euler="90 -70 0"/>
                            <geom name="toe_L2_collision" class="collision_primitive_paw" size="0.0023 0.007000000000000001" pos="0.008 0.006500000000000001 0" euler="90 -70 0"/>
                            <site name="sole_L" class="sensor" type="box" size="0.008 0.006 0.004" pos="0.003 0 -0.002"/>
                          </body>
                        </body>
                        <geom name="lower_leg_L_collision" class="collision_primitive" size="0.0075 0.022" pos="-0.01710668591579483 0.000170851114949664 -0.01495114637873932" quat="0.5843939876140521 0.278581552273902 0.3900453953818352 0.6547828460754284"/>
                      </body>
                    </body>
                    <body name="upper_leg_R" pos="-0.005866210264347091 -0.01401372452038472 -0.01205832109893569">
                      <joint name="hip_R_supinate" class="hip_supinate" axis="0 0 -1"/>
                      <joint name="hip_R_abduct" class="hip_abduct" axis="-1 0 0"/>
                      <joint name="hip_R_extend" class="hip_extend" axis="0 1 0"/>
                      <site name="knee_R" type="cylinder" size="0.0006000000000000001 0.004" pos="0.02151365485613957 -0.02438214217029151 -0.03585609142689928" zaxis="0 1 0"/>
                      <geom name="upper_leg_R0_collision" class="collision_primitive" size="0.01 0.02" pos="0.012 -0.015 -0.018" euler="-35 -40 0"/>
                      <body name="lower_leg_R" pos="0.02151365485613957 -0.02438214217029151 -0.03585609142689928">
                        <joint name="knee_R" class="knee" axis="-0.5 -1 0"/>
                        <site name="ankle_R" type="cylinder" size="0.0006000000000000001 0.0026" pos="-0.04294138476031627 0.006284105086875552 -0.02932582373875257" zaxis="0 1 0"/>
                        <body name="foot_R" pos="-0.04294138476031627 0.006284105086875552 -0.02932582373875257">
                          <joint name="ankle_R" class="ankle" axis="0.3 1 0"/>
                          <geom name="foot_R_collision" class="collision_primitive_paw" size="0.003500000000000001 0.0135" pos="0.011 -0.003 -0.003" euler="90 70 0"/>
                          <site name="toe_R" type="cylinder" size="0.0006000000000000001 0.005000000000000001" pos="0.02483323181906177 -0.008961557569487508 -0.003239117193790665" zaxis="0 1 0"/>
                          <body name="toe_R" pos="0.02483323181906177 -0.008961557569487508 -0.003239117193790665">
                            <joint name="toe_R" class="toe" axis="0 1 0"/>
                            <geom name="toe_R0_collision" class="collision_primitive_paw" size="0.0023 0.007000000000000001" pos="0.01 0.001 0" euler="90 70 0"/>
                            <geom name="toe_R1_collision" class="collision_primitive_paw" size="0.0023 0.0075" pos="0.009500000000000001 -0.003 0" euler="90 70 0"/>
                            <geom name="toe_R2_collision" class="collision_primitive_paw" size="0.0023 0.007000000000000001" pos="0.008 -0.006500000000000001 0" euler="90 70 0"/>
                            <site name="sole_R" class="sensor" type="box" size="0.008 0.006 0.004" pos="0.003 0 -0.002"/>
                          </body>
                        </body>
                        <geom name="lower_leg_R_collision" class="collision_primitive" size="0.0075 0.022" pos="-0.01677967818521928 -0.0002253924801529465 -0.01475027965238851" quat="0.6564315036111004 0.3901417719765998 0.2779576926818845 0.5827749135856758"/>
                      </body>
                    </body>
                    <body name="vertebra_C1" pos="-0.01925598991443862 0 -0.01448978405632158">
                      <body name="vertebra_C2" pos="-0.004728114368462583 0 -0.005154184395752763">
                        <body name="vertebra_C3" pos="-0.004175642454378416 0 -0.005198874922089036">
                          <body name="vertebra_C4" pos="-0.003990091056900296 0 -0.005386387990511068">
                            <body name="vertebra_C5" pos="-0.003873139354901213 0 -0.005572366901480323">
                              <body name="vertebra_C6" pos="-0.003803894939612194 0 -0.005977262538223296">
                                <body name="vertebra_C7" pos="-0.003921721060187106 0 -0.006883379429266027">
                                  <body name="vertebra_C8" pos="-0.004202260371316764 0 -0.006729489356323191">
                                    <body name="vertebra_C9" pos="-0.005225820457537256 0 -0.006237827170811349">
                                      <body name="vertebra_C10" pos="-0.005928713615418072 0 -0.005563641881295701">
                                        <body name="vertebra_C11" pos="-0.006554618274265016 0 -0.005322203864627024">
                                          <body name="vertebra_C12" pos="-0.00748107129343347 0 -0.004684759514531804">
                                            <body name="vertebra_C13" pos="-0.008411496890504038 0 -0.003161497786795132">
                                              <body name="vertebra_C14" pos="-0.008323216752858359 0 -0.001108414504015409">
                                                <body name="vertebra_C15" pos="-0.007958793986749179 0 -0.000384549996203178">
                                                  <body name="vertebra_C16" pos="-0.008163304204771352 0 -0.0001688884476288471">
                                                    <body name="vertebra_C17" pos="-0.007909056398597595 0 -2.0371550478252e-05">
                                                      <body name="vertebra_C18" pos="-0.007570039246094703 0 2.226308696857277e-10">
                                                        <body name="vertebra_C19" pos="-0.007566170241250531 0 -1.000231978948336e-09">
                                                          <body name="vertebra_C20" pos="-0.007595581487734856 0 3.068927405871233e-06">
                                                            <body name="vertebra_C21" pos="-0.007460552948132778 0 -0.0001337367949168823">
                                                            <body name="vertebra_C22" pos="-0.007936716889675491 0 -1.599984736157364e-05">
                                                            <body name="vertebra_C23" pos="-0.007793604161736542 0 2.135855378302375e-09">
                                                            <body name="vertebra_C24" pos="-0.007537457555184864 0 -1.520896552795192e-09">
                                                            <body name="vertebra_C25" pos="-0.007278291404556115 0 1.682307743632039e-10">
                                                            <body name="vertebra_C26" pos="-0.006864239731880286 0 -1.665402681646361e-09">
                                                            <body name="vertebra_C27" pos="-0.00633307351496559 0 1.702064563510047e-09">
                                                            <body name="vertebra_C28" pos="-0.006141755005428348 0 6.187783361048501e-07">
                                                            <body name="vertebra_C29" pos="-0.005821825411182596 0 -7.567749476123514e-11">
                                                            <body name="vertebra_C30" pos="-0.004884575149937963 0 -5.118516081894803e-07">
                                                            <geom name="vertebra_C30_collision" class="collision_primitive" size="0.0007787137292325497 0.00616252573672682 0.003456539940088987" density="2000.0" pos="-4.163336342344337e-17 0 0" quat="0 0.7071067811865475 0 0.7071067811865476"/>
                                                            </body>
                                                            <joint name="vertebra_C29_extend" class="caudal_extend" pos="0.002618767786771059 0 3.404117634369276e-11" axis="-0 1.000000000000001 0" range="-15 15"/>
                                                            <geom name="vertebra_C29_collision" class="collision_primitive" size="0.000778099475428462 0.005963775183772668 0.002618767786771059" density="2000.0" pos="2.775557561562891e-17 0 0" quat="0 0.7071067811865475 0 0.7071067811865476"/>
                                                            </body>
                                                            <geom name="vertebra_C28_collision" class="collision_primitive" size="0.0007780994055792689 0.005764920220826752 0.002877779770642519" density="2000.0" pos="-2.775557561562891e-17 0 0" quat="0 0.7071067811865475 0 0.7071067811865476"/>
                                                            </body>
                                                            <joint name="vertebra_C27_bend" class="caudal_bend" pos="0.003061448689550051 0 -8.227890162926245e-10" axis="-2.687580618617268e-07 0 -0.9999999999999643" range="-15 15"/>
                                                            <geom name="vertebra_C27_collision" class="collision_primitive" size="0.0008277609944343567 0.005566182837355882 0.003061448689550161" density="2000.0" pos="-2.775557561562891e-17 -6.938893903907228e-18 0" quat="0 0.7071067811865475 0 0.7071067811865476"/>
                                                            </body>
                                                            <geom name="vertebra_C26_collision" class="collision_primitive" size="0.0008277630200609565 0.005367331657907926 0.003061428898945451" density="2000.0" pos="0 0 0" quat="0 0.7071067811865475 0 0.7071067811865476"/>
                                                            </body>
                                                            <joint name="vertebra_C25_extend" class="caudal_extend" pos="0.00347892241552472 0 -8.041197849633586e-11" axis="0 1 0" range="-15 15"/>
                                                            <geom name="vertebra_C25_collision" class="collision_primitive" size="0.0008277609944343567 0.005168589268578216 0.003478922415524721" density="2000.0" pos="2.775557561562891e-17 6.938893903907228e-18 0" quat="0 0.7071067811865475 0 0.7071067811865476"/>
                                                            </body>
                                                            <geom name="vertebra_C24_collision" class="collision_primitive" size="0.0008277612039819359 0.004969772635377012 0.003478918690234423" density="2000.0" pos="0 6.938893903907228e-18 0" quat="0 0.7071067811865475 0 0.7071067811865476"/>
                                                            </body>
                                                            <joint name="vertebra_C23_bend" class="caudal_bend" pos="0.00374077633023248 0 -1.025168468675859e-09" axis="-2.740523298307198e-07 0 -0.9999999999999629" range="-15 15"/>
                                                            <geom name="vertebra_C23_collision" class="collision_primitive" size="0.0008277593879029155 0.004770975443534553 0.00374077633023262" density="2000.0" pos="0 0 0" quat="0 0.7071067811865475 0 0.7071067811865476"/>
                                                            </body>
                                                            <geom name="vertebra_C22_collision" class="collision_primitive" size="0.0008277619723230601 0.004572178106172942 0.003740778425708413" density="2000.0" pos="2.775557561562891e-17 0 0" quat="0 0.7071067811865475 0 0.7071067811865476"/>
                                                            </body>
                                                            <joint name="vertebra_C21_extend" class="caudal_extend" pos="0.003853197968248292 0 6.907187041447672e-05" axis="-0 1 0" range="-15 15"/>
                                                            <geom name="vertebra_C21_collision" class="collision_primitive" size="0.0009183091577142477 0.004972128779627383 0.003853817004710436" density="2000.0" pos="-2.775557561562891e-17 0 0" quat="0 0.7071067811865475 0 0.7071067811865476"/>
                                                            </body>
                                                            <geom name="vertebra_C20_collision" class="collision_primitive" size="0.0008989718277007341 0.005176536360522732 0.003596158232539892" density="2000.0" pos="0 3.469446951953614e-18 0" quat="0 0.7071067811865475 0 0.7071067811865476"/>
                                                          </body>
                                                          <joint name="vertebra_C19_bend" class="caudal_bend" pos="0.003596235066652267 0 4.754148007230773e-10" axis="1.321979214127503e-07 0 -0.9999999999999916" range="-15 15"/>
                                                          <geom name="vertebra_C19_collision" class="collision_primitive" size="0.0009803724009543656 0.005171378143131733 0.003596235066652298" density="2000.0" pos="0 0 0" quat="0 0.7071067811865475 0 0.7071067811865476"/>
                                                        </body>
                                                        <geom name="vertebra_C18_collision" class="collision_primitive" size="0.0009803736582398414 0.004912774951662868 0.003596230177208781" density="2000.0" pos="-5.551115123125783e-17 4.336808689942018e-19 0" quat="0 0.7071067811865475 0 0.7071067811865476"/>
                                                      </body>
                                                      <joint name="vertebra_C17_extend" class="caudal_extend" pos="0.003596207304927137 0 9.262839326265516e-06" axis="-0 1 0" range="-15 15"/>
                                                      <geom name="vertebra_C17_collision" class="collision_primitive" size="0.000980373378843069 0.004654210468288511 0.00359621923416853" density="2000.0" pos="5.551115123125783e-17 4.336808689942018e-19 0" quat="0 0.7071067811865475 0 0.7071067811865476"/>
                                                    </body>
                                                    <geom name="vertebra_C16_collision" class="collision_primitive" size="0.001126868650317192 0.004395640251459554 0.003866892773658037" density="2000.0" pos="5.551115123125783e-17 0 0" quat="0 0.7071067811865475 0 0.7071067811865476"/>
                                                  </body>
                                                  <joint name="vertebra_C15_bend" class="caudal_bend" pos="0.0038592752082805 0 0.000186470999144114" axis="0.04826131917823969 0 -0.9988347436243776" range="-15 15"/>
                                                  <geom name="vertebra_C15_collision" class="collision_primitive" size="0.001107205613516271 0.004137067589908838 0.003863777499645948" density="2000.0" pos="0 -3.469446951953614e-18 0" quat="-3.048411496515643e-15 0.6991848455046811 3.117107305228081e-15 0.7149409428873096"/>
                                                </body>
                                                <geom name="vertebra_C14_collision" class="collision_primitive" size="0.001107036438770592 0.003878506540786475 0.003863667836412787" density="2000.0" pos="-5.551115123125783e-17 -5.204170427930421e-18 0" quat="0 0.6866112770928985 0 0.7270247273434782"/>
                                              </body>
                                              <joint name="vertebra_C13_extend" class="caudal_extend" pos="0.004005019444408159 0 0.001505304023099881" axis="-0 1 0" range="-15 15"/>
                                              <geom name="vertebra_C13_collision" class="collision_primitive" size="0.001254423754289746 0.003959977824706584 0.004278565291315317" density="2000.0" pos="-1.387778780781446e-17 0 2.168404344971009e-19" quat="1.892164903646171e-16 0.6293932092262298 -2.336181429597261e-16 0.7770869888113604"/>
                                            </body>
                                            <geom name="vertebra_C12_collision" class="collision_primitive" size="0.001460128650069237 0.004146181046962738 0.004279083106666803" density="2000.0" pos="0 0 0" quat="1.235560731911126e-17 0.5080793265726891 -7.288463628123299e-18 0.8613102796956755"/>
                                          </body>
                                          <joint name="vertebra_C11_bend" class="caudal_bend" pos="0.003322170266959716 0 0.00269752816928834" axis="0.6303483586133011 0 -0.7763124028337542" range="-15 15"/>
                                          <geom name="vertebra_C11_collision" class="collision_primitive" size="0.001499795727431774 0.003896944806911051 0.0042794244363904" density="2000.0" pos="-2.775557561562891e-17 0 0" quat="8.0408085539503e-17 0.4349444185915732 -3.883920751947562e-17 0.9004573020060631"/>
                                        </body>
                                        <geom name="vertebra_C10_collision" class="collision_primitive" size="0.002052717469632626 0.005196776997763664 0.003937873989343643" density="2000.0" pos="0 0 -1.734723475976807e-18" quat="6.606927199194023e-17 0.404822478038031 -2.925028864881283e-17 0.914395298147988"/>
                                      </body>
                                      <joint name="vertebra_C9_extend" class="caudal_extend" pos="0.002528556794895996 0 0.003018224679991213" axis="-0 1 0" range="-15 15"/>
                                      <geom name="vertebra_C9_collision" class="collision_primitive" size="0.001878352090716362 0.004494897730182856 0.003937420435249805" density="2000.0" pos="0 0 -3.469446951953614e-18" quat="0.9339363308955284 -2.188685129702187e-17 0.3574394072194587 5.718710691193161e-17"/>
                                    </body>
                                    <geom name="vertebra_C8_collision" class="collision_primitive" size="0.001809490984305739 0.003957028646254912 0.003936874680221081" density="2000.0" pos="0 0 -3.469446951953614e-18" quat="0.9557562961254608 -1.801208397451436e-17 0.2941596546376485 5.852319444074877e-17"/>
                                  </body>
                                  <joint name="vertebra_C7_bend" class="caudal_bend" pos="0.001857417533831711 0 0.003260127236924199" axis="0.8688752870736811 0 -0.4950310449988247" range="-15 15"/>
                                  <geom name="vertebra_C7_collision" class="collision_primitive" size="0.001954166125506163 0.004638898652046919 0.003752123331651092" density="2000.0" pos="0 0 0" quat="-0.9587181623873691 -0.02864387142163538 -0.2629262253293439 0.1044452668751926"/>
                                </body>
                                <geom name="vertebra_C6_collision" class="collision_primitive" size="0.002309478633105755 0.004441792552825063 0.003917634021490812" density="2000.0" pos="0 0 -6.938893903907228e-18" quat="-0.9684724633255426 -0.0201653665451908 -0.2338356379719502 0.08351850206094803"/>
                              </body>
                              <joint name="vertebra_C5_extend" class="caudal_extend" pos="0.002012248229580733 0 0.00289506377246373" axis="-0 1 0" range="-15 15"/>
                              <geom name="vertebra_C5_collision" class="collision_primitive" size="0.002727197762578726 0.003776637255214155 0.003525696694850922" density="2000.0" pos="0 0 0" quat="0.959555122982002 -1.723817788817547e-17 0.2815208091047534 5.875580549826768e-17"/>
                            </body>
                            <geom name="vertebra_C4_collision" class="collision_primitive" size="0.003991695865988731 0.003851699293591082 0.004260519985109568" density="2000.0" pos="0 0 -6.938893903907228e-18" quat="0.6698964656770412 0.2263597253784533 0.2263597253784533 0.6698964656770412"/>
                          </body>
                          <joint name="vertebra_C3_bend" class="caudal_bend" pos="0.002814632916334075 0 0.003504352837554861" axis="0.7796571863505314 0 -0.6262065727633116" range="-15 15"/>
                          <geom name="vertebra_C3_collision" class="collision_primitive" size="0.00473758690059185 0.00409743981435895 0.00449473550543189" density="2000.0" pos="0 0 6.938893903907228e-18" quat="0.658413368499565 0.2578601097127201 0.2578601097127201 0.658413368499565"/>
                        </body>
                        <geom name="vertebra_C2_collision" class="collision_primitive" size="0.005016219802200794 0.003506151144392788 0.005264153238385916" density="2000.0" pos="0 0 0" quat="0.6165945006583455 0.3461375763448482 0.3461375763448482 0.6165945006583455"/>
                      </body>
                      <joint name="vertebra_C1_extend" class="caudal_extend" pos="0.004342320538000662 0 0.003267517649237096" axis="0 1 0" range="-15 15"/>
                      <geom name="vertebra_C1_collision" class="collision_primitive" size="0.006578996032476425 0.002370424568653107 0.005434373859316111" density="2000.0" pos="0 -3.388131789017201e-21 0" quat="0.5772408551843025 0.3506607415056362 0.3240276763775721 0.662447057819841"/>
                    </body>
                  </body>
                </body>
                <joint name="vertebra_5_bend" class="lumbar_bend" axis="0 0 1"/>
              </body>
              <joint name="vertebra_4_extend" class="lumbar_extend" axis="0 1 0"/>
            </body>
            <joint name="vertebra_3_twist" class="lumbar_twist" axis="1 0 0"/>
          </body>
          <joint name="vertebra_2_bend" class="lumbar_bend" axis="0 0 1"/>
        </body>
        <joint name="vertebra_1_extend" class="lumbar_extend" axis="0 1 0"/>
      </body>
      <body name="vertebra_cervical_5" pos="0.03379154265557516 1.442212667144492e-05 -0.001219896232176276">
        <geom name="vertebra_cervical_5_collision" class="nonself_collision_primitive" type="sphere" size="0.008999999999999999" density="300.0"/>
        <body name="vertebra_cervical_4" pos="0.002937854390306763 -1.465240208179275e-05 0.00098728901693379">
          <geom name="vertebra_cervical_4_collision" class="nonself_collision_primitive" type="sphere" size="0.008399999999999999" density="300.0"/>
          <body name="vertebra_cervical_3" pos="0.002622292184334463 1.473358604596558e-10 0.001148203395641312">
            <geom name="vertebra_cervical_3_collision" class="nonself_collision_primitive" type="sphere" size="0.007799999999999999" density="300.0"/>
            <body name="vertebra_cervical_2" pos="0.002317024462059503 1.565828927548445e-10 0.001066783028240731">
              <geom name="vertebra_cervical_2_collision" class="nonself_collision_primitive" type="sphere" size="0.007199999999999998" density="300.0"/>
              <body name="vertebra_cervical_1" pos="0.002167697114099282 5.514789806201078e-10 0.001140333569772667">
                <geom name="vertebra_cervical_1_collision" class="nonself_collision_primitive" type="sphere" size="0.006599999999999998" density="300.0"/>
                <body name="vertebra_axis" pos="0.002295508128227777 -2.142256692625488e-06 0.002080317812255511">
                  <geom name="vertebra_axis_collision" class="nonself_collision_primitive" type="sphere" size="0.005999999999999998" density="300.0"/>
                  <body name="vertebra_atlant" pos="0.002990466047778764 2.142664924982078e-06 0.001670188692493371">
                    <geom name="vertebra_atlant_collision" class="nonself_collision_primitive" type="sphere" size="0.005399999999999999" density="300.0"/>
                    <joint name="vertebra_atlant_extend" class="cervical_extend" pos="2.740582919998361e-05 -4.955377833772316e-08 -0.0002115292895827232" axis="0 1 0"/>
                    <body name="skull" pos="0.02865100401172017 4.604332577304655e-09 0.002159158385109813">
                      <geom name="skull_0_collision" class="collision_primitive" type="ellipsoid" size="0.02 0.015 0.01" pos="-0.01 0 0.001" euler="0 10 0"/>
                      <geom name="skull_0b_collision" class="collision_primitive" type="ellipsoid" size="0.02 0.015 0.01" density="1.0" pos="-0.01 0 0.004" euler="0 10 0"/>
                      <geom name="skull_F_collision" class="collision_primitive" type="ellipsoid" size="0.006500000000000001 0.008 0.02" pos="0.016 0 -0.001" euler="0 110 0"/>
                      <geom name="skull_Fb_collision" class="collision_primitive" type="ellipsoid" size="0.006500000000000001 0.008 0.02" density="1.0" pos="0.016 0 0.002" euler="0 110 0"/>
                      <geom name="skull_L_collision" class="collision_primitive" type="ellipsoid" size="0.006500000000000001 0.012 0.014" pos="0.006 0.005000000000000001 -0.001" euler="0 110 0"/>
                      <geom name="eye_L_collision" class="collision_primitive" type="sphere" group="1" size="0.004 0.004 0.004" rgba="0 0 0 1" pos="0.001 0.0115 0.0025"/>
                      <geom name="skull_R_collision" class="collision_primitive" type="ellipsoid" size="0.006500000000000001 0.012 0.014" pos="0.006 -0.005000000000000001 -0.001" euler="0 110 0"/>
                      <geom name="eye_R_collision" class="collision_primitive" type="sphere" group="1" size="0.004 0.004 0.004" rgba="0 0 0 1" pos="0.001 -0.0115 0.0025"/>
                      <geom name="skull_P0_collision" class="collision_primitive" type="box" size="0.006 0.005600000000000001 0.0016" pos="0.002 0 -0.007000000000000001"/>
                      <geom name="skull_P1_collision" class="collision_primitive" type="box" size="0.004 0.0036 0.0012" pos="0.007000000000000001 0 -0.007000000000000001"/>
                      <geom name="skull_P2_collision" class="collision_primitive" type="box" size="0.001 0.003 0.0008" pos="0.009500000000000001 0 -0.007000000000000001"/>
                      <geom name="skull_T0_collision" class="collision_primitive" type="ellipsoid" size="0.005000000000000001 0.006 0.004" pos="0.033 0 -0.008" euler="0 30 0"/>
                      <geom name="skull_T1_collision" class="collision_primitive" type="ellipsoid" group="1" size="0.002 0.0015 0.007000000000000001" rgba="1 1 1 1" pos="0.031 0.001 -0.015" euler="0 30 0"/>
                      <geom name="skull_T2_collision" class="collision_primitive" type="ellipsoid" group="1" size="0.002 0.0015 0.007000000000000001" rgba="1 1 1 1" pos="0.031 -0.001 -0.015" euler="0 30 0"/>
                      <joint name="atlas" class="atlas" pos="-0.02843583549004804 0 0"/>
                      <site name="head" class="sensor" type="box" size="0.002 0.002 0.002"/>
                      <camera name="egocentric" fovy="80.0" pos="0.01 0 0.005" euler="0 -90 -90"/>
                      <body name="jaw" pos="0.0005 -1.740775010796468e-08 -0.02" euler="0 15 0">
                        <geom name="jaw_back_collision" class="collision_primitive" type="ellipsoid" size="0.011 0.012 0.007000000000000001" pos="-0.012 0 0.0025" euler="0 55 0"/>
                        <geom name="jaw_F_collision" class="collision_primitive" type="ellipsoid" size="0.003 0.006 0.012" pos="0.003 0 -0.006" euler="0 105 0"/>
                        <geom name="jaw_L_collision" class="collision_primitive" type="ellipsoid" size="0.008999999999999999 0.003500000000000001 0.016" pos="-0.006 0.008999999999999999 0.001" euler="-40 125 30"/>
                        <geom name="jaw_R_collision" class="collision_primitive" type="ellipsoid" size="0.008999999999999999 0.003500000000000001 0.016" pos="-0.006 -0.008999999999999999 0.001" euler="40 125 -30"/>
                        <geom name="jaw_T0_collision" class="collision_primitive" type="ellipsoid" size="0.003 0.003 0.006" pos="0.014 0 -0.007000000000000001" euler="0 70 0"/>
                        <geom name="jaw_T1_collision" class="collision_primitive" type="ellipsoid" group="1" size="0.002 0.0012 0.007000000000000001" rgba="1 1 1 1" pos="0.019 0.001 -0.005000000000000001" euler="0 65 0"/>
                        <geom name="jaw_T2_collision" class="collision_primitive" type="ellipsoid" group="1" size="0.002 0.0012 0.007000000000000001" rgba="1 1 1 1" pos="0.019 -0.001 -0.005000000000000001" euler="0 65 0"/>
                        <geom name="jaw_P0_collision" class="collision_primitive" type="box" size="0.006 0.005600000000000001 0.0016" pos="-0.003 0 0.001" euler="0 55 0"/>
                        <geom name="jaw_P1_collision" class="collision_primitive" type="box" size="0.004 0.0044 0.001" pos="0 0 -0.0012" euler="0 30 0"/>
                        <geom name="jaw_P2_collision" class="collision_primitive" type="box" size="0.004 0.0036 0.001" pos="0.003 0 -0.0028" euler="0 25 0"/>
                        <geom name="jaw_P3_collision" class="collision_primitive" type="box" size="0.003 0.0026 0.0006000000000000001" pos="0.0052 0 -0.003500000000000001" euler="0 15 0"/>
                        <joint name="mandible" class="mandible" pos="-0.0185 0 0.004" axis="0 1 0"/>
                      </body>
                    </body>
                  </body>
                  <joint name="vertebra_axis_twist" class="cervical_twist" pos="9.943926722569324e-05 7.332304159315717e-08 -0.0002676240089982131" axis="0.7409845944832573 -0.0006915153935393208 0.6715216694529994"/>
                </body>
                <joint name="vertebra_cervical_1_bend" class="cervical_bend" pos="2.74698396710647e-05 -2.217570324196948e-11 -0.0002637692890460073" axis="-0.4655674978646318 0 0.885012375581277"/>
              </body>
              <joint name="vertebra_cervical_2_extend" class="cervical_extend" pos="1.295156098152258e-05 -5.795372986069688e-12 -0.0002538748472657769" axis="0 1 0"/>
            </body>
            <joint name="vertebra_cervical_3_twist" class="cervical_twist" pos="8.197570870224901e-06 -4.86590177453699e-12 -0.0002544294736271219" axis="0.9160353567291684 5.146827584715309e-08 0.4010975258239107"/>
          </body>
          <joint name="vertebra_cervical_4_bend" class="cervical_bend" pos="-1.537595270261077e-05 4.797260713088921e-07 -0.0002727908789887391" axis="-0.3185475796000196 0 0.9478950836057671"/>
        </body>
        <joint name="vertebra_cervical_5_extend" class="cervical_extend" pos="-0.0001934586467415268 -3.998580249810072e-07 -0.0002296866127457893" axis="0 1 0"/>
      </body>
      <body name="scapula_L" pos="0.008 0.002 0.014">
        <joint name="scapula_L_supinate" class="scapula_supinate" pos="0 -0.005000000000000001 0" axis="-0 -0 1"/>
        <joint name="scapula_L_abduct" class="scapula_abduct" pos="0 -0.005000000000000001 -0.01" axis="1 -0 -0"/>
        <joint name="scapula_L_extend" class="scapula_extend" pos="0 0 0" axis="0.3 1 0"/>
        <site name="shoulder_L" size="0.002" pos="0.035 0.012 -0.031"/>
        <body name="upper_arm_L" pos="0.035 0.012 -0.031">
          <joint name="shoulder_L" class="shoulder" axis="0 1 0"/>
          <joint name="shoulder_sup_L" class="shoulder_sup" axis="0 0 -1"/>
          <site name="elbow_L" type="cylinder" size="0.0006000000000000001 0.004" pos="-0.02 0.013 -0.028" zaxis="0 1 0.2"/>
          <body name="lower_arm_L" pos="-0.02 0.013 -0.028">
            <joint name="elbow_L" class="elbow" axis="0 1 0.2"/>
            <site name="wrist_L" type="cylinder" size="0.0008 0.0034" pos="0.024 0.014 -0.022" zaxis="0 1 0"/>
            <body name="hand_L" pos="0.024 0.014 -0.022">
              <joint name="wrist_L" class="wrist" axis="0.6 -1 0"/>
              <geom name="hand_L_collision" class="collision_primitive_paw" type="ellipsoid" size="0.007000000000000001 0.004 0.0024" pos="0.002 0.001 -0.006" euler="-40 50 45"/>
              <site name="finger_L" type="cylinder" size="0.0006000000000000001 0.005000000000000001" pos="0.004 0.002 -0.011" zaxis="-0.2 1 0"/>
              <body name="finger_L" pos="0.004 0.002 -0.011">
                <joint name="finger_L" class="finger" axis="-0.5 1 0"/>
                <geom name="finger_L0_collision" class="collision_primitive_paw" size="0.002 0.003500000000000001" pos="0.006500000000000001 -0.001 0" euler="90 -75 0"/>
                <geom name="finger_L1_collision" class="collision_primitive_paw" size="0.002 0.004" pos="0.006 0.0025 0" euler="90 -63 0"/>
                <geom name="finger_L2_collision" class="collision_primitive_paw" size="0.002 0.003500000000000001" pos="0.003500000000000001 0.005000000000000001 0" euler="90 -55 0"/>
                <site name="palm_L" class="sensor" type="box" size="0.008 0.006 0.004" pos="0.003 0 -0.001"/>
              </body>
            </body>
            <geom name="radius_L_collision" class="collision_primitive" size="0.0034 0.0145" pos="0.0127822681052473 0.007610990103404512 -0.01358313664233387" quat="0.02376493230846292 0.7917721441518218 0.4232293467931716 0.4397829234413568"/>
            <geom name="ulna_L_collision" class="collision_primitive" size="0.004 0.012" pos="0.007498816880968415 0.005546450402240478 -0.01054298075297904" quat="0.01282244452041863 0.7446249872782607 0.4776065607195328 0.4661128472752391"/>
          </body>
          <geom name="humerus_L_collision" class="collision_primitive" size="0.008 0.016" pos="-0.009720975677976487 0.00726621453790172 -0.01504387170819723" quat="0.472560999180163 0.3450082805420177 0.0007016050154913519 0.8109592444517103"/>
        </body>
        <geom name="scapula_L_collision" class="nonself_collision_primitive" type="ellipsoid" size="0.005005370825529099 0.01463182792067528 0.02431104406714439" pos="0.02142758842760323 0.0105328252196495 -0.01857258840570356" quat="0.1844194062696375 0.7692222855376651 0.4740322845517004 0.3867556738123709"/>
      </body>
      <body name="scapula_R" pos="0.008 -0.002 0.014">
        <joint name="scapula_R_supinate" class="scapula_supinate" pos="0 0.005000000000000001 0" axis="0 0 -1"/>
        <joint name="scapula_R_abduct" class="scapula_abduct" pos="0 0.005000000000000001 -0.01" axis="-1 0 0"/>
        <joint name="scapula_R_extend" class="scapula_extend" pos="0 0 0" axis="-0.3 1 0"/>
        <site name="shoulder_R" size="0.002" pos="0.035 -0.012 -0.031"/>
        <body name="upper_arm_R" pos="0.035 -0.012 -0.031">
          <joint name="shoulder_R" class="shoulder" axis="0 1 0"/>
          <joint name="shoulder_sup_R" class="shoulder_sup" axis="-0 -0 1"/>
          <site name="elbow_R" type="cylinder" size="0.0006000000000000001 0.004" pos="-0.02 -0.013 -0.028" zaxis="0 1 -0.2"/>
          <body name="lower_arm_R" pos="-0.02 -0.013 -0.028">
            <joint name="elbow_R" class="elbow" axis="0 1 -0.2"/>
            <site name="wrist_R" type="cylinder" size="0.0008 0.0034" pos="0.024 -0.014 -0.022" zaxis="0 1 0"/>
            <body name="hand_R" pos="0.024 -0.014 -0.022">
              <joint name="wrist_R" class="wrist" axis="-0.6 -1 0"/>
              <geom name="hand_R_collision" class="collision_primitive_paw" type="ellipsoid" size="0.007000000000000001 0.004 0.0024" pos="0.002 -0.001 -0.006" euler="40 50 -45"/>
              <site name="finger_R" type="cylinder" size="0.0006000000000000001 0.005000000000000001" pos="0.004 -0.002 -0.011" zaxis="0.2 1 0"/>
              <body name="finger_R" pos="0.004 -0.002 -0.011">
                <joint name="finger_R" class="finger" axis="0.5 1 0"/>
                <geom name="finger_R0_collision" class="collision_primitive_paw" size="0.002 0.003500000000000001" pos="0.006500000000000001 0.001 0" euler="90 75 0"/>
                <geom name="finger_R1_collision" class="collision_primitive_paw" size="0.002 0.004" pos="0.006 -0.0025 0" euler="90 63 0"/>
                <geom name="finger_R2_collision" class="collision_primitive_paw" size="0.002 0.003500000000000001" pos="0.003500000000000001 -0.005000000000000001 0" euler="90 55 0"/>
                <site name="palm_R" class="sensor" type="box" size="0.008 0.006 0.004" pos="0.003 0 -0.001"/>
              </body>
            </body>
            <geom name="radius_R_collision" class="collision_primitive" size="0.0034 0.0145" pos="0.01278227557156809 -0.007611481161884252 -0.01358314224175167" quat="0.4397828585901176 0.423230473256099 0.7917715587074765 0.02376557635859348"/>
            <geom name="ulna_R_collision" class="collision_primitive" size="0.004 0.012" pos="0.00749881973306904 -0.005546939323690665 -0.01054298081390906" quat="0.4661127828257156 0.4776067795325061 0.7446248854693838 0.01282254930824632"/>
          </body>
          <geom name="humerus_R_collision" class="collision_primitive" size="0.008 0.016" pos="-0.00972097246346848 -0.007266677365917205 -0.01504386911456862" quat="0.8109593935310486 0.0007013948082913995 0.3450082795040448 0.4725607444157158"/>
        </body>
        <geom name="scapula_R_collision" class="nonself_collision_primitive" type="ellipsoid" size="0.005005370266735553 0.01463183127343655 0.02431103959679604" pos="0.02142758559573723 -0.01053328691142344 -0.01857258613184139" quat="0.3867556972129688 0.4740321312040688 0.7692223496423682 0.1844194839763772"/>
      </body>
    </body>
    <!-- <geom name="terrain" type="hfield" rgba="0.2 0.3 0.4 1" pos="0 0 -0.01" hfield="terrain"/> -->
  </worldbody>
  <contact>
    <exclude name="pelvis:vertebra_C3" body1="pelvis" body2="vertebra_C3"/>
    <exclude name="pelvis:vertebra_C4" body1="pelvis" body2="vertebra_C4"/>
    <exclude name="vertebra_axis:skull" body1="vertebra_axis" body2="skull"/>
  </contact>
  <tendon>
    <fixed name="lumbar_extend" class="lumbar_extend">
      <joint joint="vertebra_1_extend" coef="0.611232384148"/>
      <joint joint="vertebra_4_extend" coef="0.388767615852"/>
    </fixed>
    <fixed name="lumbar_bend" class="lumbar_bend">
      <joint joint="vertebra_2_bend" coef="0.673440169021"/>
      <joint joint="vertebra_5_bend" coef="0.326559830979"/>
    </fixed>
    <fixed name="lumbar_twist" class="lumbar_twist">
      <joint joint="vertebra_3_twist" coef="0.567275016346"/>
      <joint joint="vertebra_6_twist" coef="0.432724983654"/>
    </fixed>
    <fixed name="cervical_extend" class="cervical_extend">
      <joint joint="vertebra_cervical_5_extend" coef="0.341713547174"/>
      <joint joint="vertebra_cervical_2_extend" coef="0.332408292936"/>
      <joint joint="vertebra_atlant_extend" coef="0.32587815989"/>
    </fixed>
    <fixed name="cervical_bend" class="cervical_bend">
      <joint joint="vertebra_cervical_4_bend" coef="0.50743949691"/>
      <joint joint="vertebra_cervical_1_bend" coef="0.49256050309"/>
    </fixed>
    <fixed name="cervical_twist" class="cervical_twist">
      <joint joint="vertebra_cervical_3_twist" coef="0.496142185731"/>
      <joint joint="vertebra_axis_twist" coef="0.503857814269"/>
    </fixed>
    <fixed name="caudal_extend" class="caudal_extend">
      <joint joint="vertebra_C1_extend" coef="0.427378558354"/>
      <joint joint="vertebra_C5_extend" coef="0.255659487498"/>
      <joint joint="vertebra_C9_extend" coef="0.162015531448"/>
      <joint joint="vertebra_C13_extend" coef="0.0908820320559"/>
      <joint joint="vertebra_C17_extend" coef="0.0419255178006"/>
      <joint joint="vertebra_C21_extend" coef="0.0165806599147"/>
      <joint joint="vertebra_C25_extend" coef="0.00419149795848"/>
      <joint joint="vertebra_C29_extend" coef="0.00136671497022"/>
    </fixed>
    <fixed name="caudal_bend" class="caudal_bend">
      <joint joint="vertebra_C3_bend" coef="0.465959582647"/>
      <joint joint="vertebra_C7_bend" coef="0.208208889814"/>
      <joint joint="vertebra_C11_bend" coef="0.156709309744"/>
      <joint joint="vertebra_C15_bend" coef="0.105497877966"/>
      <joint joint="vertebra_C19_bend" coef="0.0454826232883"/>
      <joint joint="vertebra_C23_bend" coef="0.0146832624497"/>
      <joint joint="vertebra_C27_bend" coef="0.00345845409169"/>
    </fixed>
  </tendon>
  <actuator>
    <general name="lumbar_extend" forcerange="-20 20" tendon="lumbar_extend" dyntype="filter" biastype="affine" dynprm="0.08" gainprm="7.853981633974483" biasprm="-2.617993877991494 -20"/>
    <general name="lumbar_bend" forcerange="-20 20" tendon="lumbar_bend" dyntype="filter" biastype="affine" dynprm="0.08" gainprm="10.47197551196598" biasprm="0 -20"/>
    <general name="lumbar_twist" forcerange="-20 20" tendon="lumbar_twist" dyntype="filter" biastype="affine" dynprm="0.08" gainprm="10.47197551196598" biasprm="0 -20"/>
    <general name="cervical_extend" forcerange="-20 20" tendon="cervical_extend" dyntype="filter" biastype="affine" dynprm="0.08" gainprm="10.18108730330026" biasprm="2.03621746066005 -20"/>
    <general name="cervical_bend" forcerange="-20 20" tendon="cervical_bend" dyntype="filter" biastype="affine" dynprm="0.08" gainprm="12.21730476396031" biasprm="0 -20"/>
    <general name="cervical_twist" forcerange="-20 20" tendon="cervical_twist" dyntype="filter" biastype="affine" dynprm="0.08" gainprm="12.21730476396031" biasprm="0 -20"/>
    <general name="caudal_extend" forcerange="-0.1 0.1" tendon="caudal_extend" dyntype="filter" biastype="affine" dynprm="0.08" gainprm="0.02617993877991495" biasprm="0 -0.1"/>
    <general name="caudal_bend" forcerange="-0.1 0.1" tendon="caudal_bend" dyntype="filter" biastype="affine" dynprm="0.08" gainprm="0.02617993877991494" biasprm="0 -0.1"/>
    <general name="hip_L_supinate" forcerange="-0.15 0.15" joint="hip_L_supinate" dyntype="filter" biastype="affine" dynprm="0.08" gainprm="0.1570796326794896" biasprm="0 -0.3"/>
    <general name="hip_L_abduct" forcerange="-0.15 0.15" joint="hip_L_abduct" dyntype="filter" biastype="affine" dynprm="0.08" gainprm="0.2094395102393195" biasprm="0.1047197551196598 -0.3"/>
    <general name="hip_L_extend" forcerange="-0.15 0.15" joint="hip_L_extend" dyntype="filter" biastype="affine" dynprm="0.08" gainprm="0.3926990816987241" biasprm="-0.07853981633974484 -0.3"/>
    <general name="knee_L" forcerange="-0.075 0.075" joint="knee_L" dyntype="filter" biastype="affine" dynprm="0.08" gainprm="0.206821516361328" biasprm="0.02356194490192345 -0.15"/>
    <general name="ankle_L" forcerange="-0.05 0.05" joint="ankle_L" dyntype="filter" biastype="affine" dynprm="0.08" gainprm="0.0767944870877505" biasprm="0.06283185307179587 -0.1"/>
    <general name="toe_L" forcerange="-0.0025 0.0025" joint="toe_L" dyntype="filter" biastype="affine" dynprm="0.08" gainprm="0.002181661564992912" biasprm="0.002181661564992912 -0.005"/>
    <general name="hip_R_supinate" forcerange="-0.15 0.15" joint="hip_R_supinate" dyntype="filter" biastype="affine" dynprm="0.08" gainprm="0.1570796326794896" biasprm="0 -0.3"/>
    <general name="hip_R_abduct" forcerange="-0.15 0.15" joint="hip_R_abduct" dyntype="filter" biastype="affine" dynprm="0.08" gainprm="0.2094395102393195" biasprm="0.1047197551196598 -0.3"/>
    <general name="hip_R_extend" forcerange="-0.15 0.15" joint="hip_R_extend" dyntype="filter" biastype="affine" dynprm="0.08" gainprm="0.3926990816987241" biasprm="-0.07853981633974484 -0.3"/>
    <general name="knee_R" forcerange="-0.075 0.075" joint="knee_R" dyntype="filter" biastype="affine" dynprm="0.08" gainprm="0.206821516361328" biasprm="0.02356194490192345 -0.15"/>
    <general name="ankle_R" forcerange="-0.05 0.05" joint="ankle_R" dyntype="filter" biastype="affine" dynprm="0.08" gainprm="0.0767944870877505" biasprm="0.06283185307179587 -0.1"/>
    <general name="toe_R" forcerange="-0.0025 0.0025" joint="toe_R" dyntype="filter" biastype="affine" dynprm="0.08" gainprm="0.002181661564992912" biasprm="0.002181661564992912 -0.005"/>
    <general name="atlas" forcerange="-0.025 0.025" joint="atlas" dyntype="filter" biastype="affine" dynprm="0.08" gainprm="0.02181661564992912" biasprm="0.0174532925199433 -0.05"/>
    <general name="mandible" forcerange="-0.025 0.025" joint="mandible" dyntype="filter" biastype="affine" dynprm="0.08" gainprm="0.01396263401595464" biasprm="-0.000872664625997166 -0.05"/>
    <general name="scapula_L_supinate" forcerange="-0.25 0.25" joint="scapula_L_supinate" dyntype="filter" biastype="affine" dynprm="0.08" gainprm="0.04799655442984406" biasprm="0.03926990816987241 -0.5"/>
    <general name="scapula_L_abduct" forcerange="-0.25 0.25" joint="scapula_L_abduct" dyntype="filter" biastype="affine" dynprm="0.08" gainprm="0.1308996938995747" biasprm="0 -0.5"/>
    <general name="scapula_L_extend" forcerange="-0.25 0.25" joint="scapula_L_extend" dyntype="filter" biastype="affine" dynprm="0.08" gainprm="0.0174532925199433" biasprm="0 -0.5"/>
    <general name="shoulder_L" forcerange="-0.15 0.15" joint="shoulder_L" dyntype="filter" biastype="affine" dynprm="0.08" gainprm="0.3272492347489368" biasprm="-0.06544984694978737 -0.3"/>
    <general name="shoulder_sup_L" forcerange="-0.15 0.15" joint="shoulder_sup_L" dyntype="filter" biastype="affine" dynprm="0.08" gainprm="0.1256637061435917" biasprm="0.1099557428756428 -0.3"/>
    <general name="elbow_L" forcerange="-0.15 0.15" joint="elbow_L" dyntype="filter" biastype="affine" dynprm="0.08" gainprm="0.2748893571891069" biasprm="-0.1178097245096173 -0.3"/>
    <general name="wrist_L" forcerange="-0.05 0.05" joint="wrist_L" dyntype="filter" biastype="affine" dynprm="0.08" gainprm="0.1221730476396031" biasprm="0.08726646259971647 -0.1"/>
    <general name="finger_L" forcerange="-0.025 0.025" joint="finger_L" dyntype="filter" biastype="affine" dynprm="0.08" gainprm="0.03926990816987241" biasprm="0.03926990816987241 -0.05"/>
    <general name="scapula_R_supinate" forcerange="-0.25 0.25" joint="scapula_R_supinate" dyntype="filter" biastype="affine" dynprm="0.08" gainprm="0.04799655442984406" biasprm="0.03926990816987241 -0.5"/>
    <general name="scapula_R_abduct" forcerange="-0.25 0.25" joint="scapula_R_abduct" dyntype="filter" biastype="affine" dynprm="0.08" gainprm="0.1308996938995747" biasprm="0 -0.5"/>
    <general name="scapula_R_extend" forcerange="-0.25 0.25" joint="scapula_R_extend" dyntype="filter" biastype="affine" dynprm="0.08" gainprm="0.0174532925199433" biasprm="0 -0.5"/>
    <general name="shoulder_R" forcerange="-0.15 0.15" joint="shoulder_R" dyntype="filter" biastype="affine" dynprm="0.08" gainprm="0.3272492347489368" biasprm="-0.06544984694978737 -0.3"/>
    <general name="shoulder_sup_R" forcerange="-0.15 0.15" joint="shoulder_sup_R" dyntype="filter" biastype="affine" dynprm="0.08" gainprm="0.1256637061435917" biasprm="0.1099557428756428 -0.3"/>
    <general name="elbow_R" forcerange="-0.15 0.15" joint="elbow_R" dyntype="filter" biastype="affine" dynprm="0.08" gainprm="0.2748893571891069" biasprm="-0.1178097245096173 -0.3"/>
    <general name="wrist_R" forcerange="-0.05 0.05" joint="wrist_R" dyntype="filter" biastype="affine" dynprm="0.08" gainprm="0.1221730476396031" biasprm="0.08726646259971647 -0.1"/>
    <general name="finger_R" forcerange="-0.025 0.025" joint="finger_R" dyntype="filter" biastype="affine" dynprm="0.08" gainprm="0.03926990816987241" biasprm="0.03926990816987241 -0.05"/>
  </actuator>
  <sensor>
    <accelerometer name="accelerometer" site="head"/>
    <velocimeter name="velocimeter" site="head"/>
    <gyro name="gyro" site="head"/>
    <touch name="palm_L" site="palm_L"/>
    <touch name="palm_R" site="palm_R"/>
    <touch name="sole_L" site="sole_L"/>
    <touch name="sole_R" site="sole_R"/>
    <subtreelinvel name="torso" body="torso"/>
  </sensor>
  <compiler meshdir="./"/>
  <size njmax="8000" nconmax="4000"/>
</mujoco>
